Workbook

Sheet DETAILS
H2: XEROX
A3: 1 | B3: PAN & AADHAR CARD & PHOTO | H3: YES
A4: 2 | B4: NAME AS PER PAN
A5: 3 | B5: TRADE NAME & NATURE OF BUSINES | C5: 1
B6: SHOP ACT LICENCE / SSI /MSME | C6: 2 | H6: YES
C7: 3
C8: 4
A9: 4 | B9: PRINCIPAL PLACE OF BUSINESS | H9: YES
A10: 5 | B10: ADDITIONAL PLACE OF BUSINESS /GODOWN | H10: YES
B11: owner +TAX RECEIPT | C11: 1
B12: RENT AGREEMENT + TAX RECEIPT | C12: 2 | H12: YES
B13: CONSENT LETTER + TAX RECEIPT | C13: 3 | H13: YES
B14: LEASE AGREEMENT + TAX RECEIPT | C14: 4 | H14: YES
A15: 6 | B15: NAME OF COMMODITY & HSN CODE | C15: 1
C16: 2
C17: 3
C18: 4
C19: 5
A20: 7 | B20: NATURE OF SERVICES & SAC CODE | C20: 1
C21: 2
C22: 3
C23: 4
C24: 5
A25: 6 | B25: DETAILS OF PROPRIETOR/PARTNE/DIRECTOR
B26: NAME AS PER PAN
B27: DESIGNATION
B28: MOBILE NUMBER
B29: LANDLINE NUMBER
B30: E-MAIL ADDRESS
A31: 7 | B31: NAME OF THE CONTACT PERSON / ACCOUNTANT
B32: NAME
B33: DESIGNATION
B34: MOBILE NUMBER
B35: E-MAIL ADDRESS
A36: 8 | B36: DETIALS OF BANK ACCOUNTS | D36: NAME OF THE BANK
B37: NAME OF THE BANK | D37: ADDRESS OF THE BRANCH | E37: SB/CA/CC | F37: A/C.NO | G37: IFSC
A38: 1
A39: 2
A40: 3
A41: 4
...

Sheet I-T
B2: NAME = | C2: =Yearly!C2 -> 0 | J2: As per Books
B4: Total | J4: =SUM(J6:J13) -> 0 | K4: =SUM(K6:K13) -> 0 | L4: =SUM(L6:L13) -> 0 | M4: =SUM(M6:M13) -> 0 | N4: =SUM(N6:N13) -> 0 | O4: =SUM(O6:O13) -> 0 | P4: =SUM(P6:P13) -> 0 | Q4: =SUM(Q6:Q13) -> 0
B5: Difference | C5: GSTIN = | D5: =Yearly!D5 -> 0 | J5: =SUM(J17:J216)-J4 -> 0 | K5: =SUM(K17:K216)-K4 -> 0 | L5: =SUM(L17:L216)-L4 -> 0 | M5: =SUM(M17:M216)-M4 -> 0 | N5: =SUM(N17:N216)-N4 -> 0 | O5: =SUM(O17:O216)-O4 -> 0 | P5: =SUM(P17:P216)-P4 -> 0 | Q5: =SUM(Q17:Q216)-Q4 -> 0
B6: Sales | J6: =SUMIF($B$17:$Q$516, B6, $J$17:$J$516) -> 0 | K6: =SUMIF($B$17:$Q$516, B6, $K$17:$K$516) -> 0 | L6: =SUMIF($B$17:$Q$516, B6, $L$17:$L$516) -> 0 | M6: =SUMIF($B$17:$Q$516, B6, $M$17:$M$516) -> 0 | N6: =SUMIF($B$17:$Q$516, B6, $N$17:$N$516) -> 0 | O6: =SUMIF($B$17:$Q$516, B6, $O$17:$O$516) -> 0 | P6: =SUMIF($B$17:$Q$516, B6, $P$17:$P$516) -> 0 | Q6: =SUMIF($B$17:$Q$516, B6, $Q$17:$Q$516) -> 0
B7: Direct Incomes | J7: =SUMIF($B$17:$Q$516, B7, $J$17:$J$516) -> 0 | K7: =SUMIF($B$17:$Q$516, B7, $K$17:$K$516) -> 0 | L7: =SUMIF($B$17:$Q$516, B7, $L$17:$L$516) -> 0 | M7: =SUMIF($B$17:$Q$516, B7, $M$17:$M$516) -> 0 | N7: =SUMIF($B$17:$Q$516, B7, $N$17:$N$516) -> 0 | O7: =SUMIF($B$17:$Q$516, B7, $O$17:$O$516) -> 0 | P7: =SUMIF($B$17:$Q$516, B7, $P$17:$P$516) -> 0 | Q7: =SUMIF($B$17:$Q$516, B7, $Q$17:$Q$516) -> 0
B8: Indirect Incomes | C8: YEAR = | D8: =Yearly!D8 -> 2017-18 | J8: =SUMIF($B$17:$Q$516, B8, $J$17:$J$516) -> 0 | K8: =SUMIF($B$17:$Q$516, B8, $K$17:$K$516) -> 0 | L8: =SUMIF($B$17:$Q$516, B8, $L$17:$L$516) -> 0 | M8: =SUMIF($B$17:$Q$516, B8, $M$17:$M$516) -> 0 | N8: =SUMIF($B$17:$Q$516, B8, $N$17:$N$516) -> 0 | O8: =SUMIF($B$17:$Q$516, B8, $O$17:$O$516) -> 0 | P8: =SUMIF($B$17:$Q$516, B8, $P$17:$P$516) -> 0 | Q8: =SUMIF($B$17:$Q$516, B8, $Q$17:$Q$516) -> 0
B9: Purchases | J9: =SUMIF($B$17:$Q$516, B9, $J$17:$J$516) -> 0 | K9: =SUMIF($B$17:$Q$516, B9, $K$17:$K$516) -> 0 | L9: =SUMIF($B$17:$Q$516, B9, $L$17:$L$516) -> 0 | M9: =SUMIF($B$17:$Q$516, B9, $M$17:$M$516) -> 0 | N9: =SUMIF($B$17:$Q$516, B9, $N$17:$N$516) -> 0 | O9: =SUMIF($B$17:$Q$516, B9, $O$17:$O$516) -> 0 | P9: =SUMIF($B$17:$Q$516, B9, $P$17:$P$516) -> 0 | Q9: =SUMIF($B$17:$Q$516, B9, $Q$17:$Q$516) -> 0
B10: Direct Expenses | J10: =SUMIF($B$17:$Q$516, B10, $J$17:$J$516) -> 0 | K10: =SUMIF($B$17:$Q$516, B10, $K$17:$K$516) -> 0 | L10: =SUMIF($B$17:$Q$516, B10, $L$17:$L$516) -> 0 | M10: =SUMIF($B$17:$Q$516, B10, $M$17:$M$516) -> 0 | N10: =SUMIF($B$17:$Q$516, B10, $N$17:$N$516) -> 0 | O10: =SUMIF($B$17:$Q$516, B10, $O$17:$O$516) -> 0 | P10: =SUMIF($B$17:$Q$516, B10, $P$17:$P$516) -> 0 | Q10: =SUMIF($B$17:$Q$516, B10, $Q$17:$Q$516) -> 0
B11: Indirect Expenses | C11: MONTH = | D11: APRIL TO MARCH | J11: =SUMIF($B$17:$Q$516, B11, $J$17:$J$516) -> 0 | K11: =SUMIF($B$17:$Q$516, B11, $K$17:$K$516) -> 0 | L11: =SUMIF($B$17:$Q$516, B11, $L$17:$L$516) -> 0 | M11: =SUMIF($B$17:$Q$516, B11, $M$17:$M$516) -> 0 | N11: =SUMIF($B$17:$Q$516, B11, $N$17:$N$516) -> 0 | O11: =SUMIF($B$17:$Q$516, B11, $O$17:$O$516) -> 0 | P11: =SUMIF($B$17:$Q$516, B11, $P$17:$P$516) -> 0 | Q11: =SUMIF($B$17:$Q$516, B11, $Q$17:$Q$516) -> 0
B12: Capital Assets | J12: =SUMIF($B$17:$Q$516, B12, $J$17:$J$516) -> 0 | K12: =SUMIF($B$17:$Q$516, B12, $K$17:$K$516) -> 0 | L12: =SUMIF($B$17:$Q$516, B12, $L$17:$L$516) -> 0 | M12: =SUMIF($B$17:$Q$516, B12, $M$17:$M$516) -> 0 | N12: =SUMIF($B$17:$Q$516, B12, $N$17:$N$516) -> 0 | O12: =SUMIF($B$17:$Q$516, B12, $O$17:$O$516) -> 0 | P12: =SUMIF($B$17:$Q$516, B12, $P$17:$P$516) -> 0 | Q12: =SUMIF($B$17:$Q$516, B12, $Q$17:$Q$516) -> 0
B13: Others | J13: =SUMIF($B$17:$Q$516, B13, $J$17:$J$516) -> 0 | K13: =SUMIF($B$17:$Q$516, B13, $K$17:$K$516) -> 0 | L13: =SUMIF($B$17:$Q$516, B13, $L$17:$L$516) -> 0 | M13: =SUMIF($B$17:$Q$516, B13, $M$17:$M$516) -> 0 | N13: =SUMIF($B$17:$Q$516, B13, $N$17:$N$516) -> 0 | O13: =SUMIF($B$17:$Q$516, B13, $O$17:$O$516) -> 0 | P13: =SUMIF($B$17:$Q$516, B13, $P$17:$P$516) -> 0 | Q13: =SUMIF($B$17:$Q$516, B13, $Q$17:$Q$516) -> 0
A15: Sr. No. | B15: Nature of Transaction | C15: Head as per Financial Statements | D15: Type of Item | E15: Type of Dealer | F15: Document | G15: HSN | H15: Tax Rate | J15: Total Amount as per Profit & Loss | K15: Non GST liable | L15: in respect of entities registered under GST | P15: Relating to entities not registered under GST | Q15: Difference
L16: Relating to goods or services exempt from GST | M16: Relating to entities falling under composition scheme | N16: Relating to other registered entities | O16: Total payment to registered entities
A17: 1 | B17: =Yearly!B16 -> 0 | C17: =Yearly!C16 -> 0 | D17: =Yearly!D16 -> 0 | E17: =Yearly!E16 -> 0 | F17: =Yearly!F16 -> 0 | G17: =Yearly!G16 -> 0 | H17: =Yearly!H16 -> 0 | K17: =Apr!P16+May!P16+Jun!P16+Jul!P16+Aug!P16+Sep!P16+Oct!P16+Nov!P16+Dec!P16+Jan!P16+Feb!P16+Mar!P16 -> 0 | L17: =IF(H17="Exempt", (Apr!Q16+May!Q16+Jun!Q16+Jul!Q16+Aug!Q16+Sep!Q16+Oct!Q16+Nov!Q16+Dec!Q16+Jan!Q16+Feb!Q16+Mar!Q16)+(Apr!P16+May!P16+Jun!P16+Jul!P16+Aug!P16+Sep!P16+Oct!P16+Nov!P16+Dec!P16+Jan!P16+Feb!P16+Mar!P16),0) -> 0 | M17: =IF(E17="Composition", (Apr!Q16+May!Q16+Jun!Q16+Jul!Q16+Aug!Q16+Sep!Q16+Oct!Q16+Nov!Q16+Dec!Q16+Jan!Q16+Feb!Q16+Mar!Q16)+(Apr!P16+May!P16+Jun!P16+Jul!P16+Aug!P16+Sep!P16+Oct!P16+Nov!P16+Dec!P16+Jan!P16+Feb!P16+Mar!P16),0) -> 0 | N17: =IF(E17="Registered", (Apr!J16+May!J16+Jun!J16+Jul!J16+Aug!J16+Sep!J16+Oct!J16+Nov!J16+Dec!J16+Jan!J16+Feb!J16+Mar!J16),0) -> 0 | O17: =SUM(L17:N17) -> 0 | P17: =IF(E17="Un-registered", (Apr!J16+May!J16+Jun!J16+Jul!J16+Aug!J16+Sep!J16+Oct!J16+Nov!J16+Dec!J16+Jan!J16+Feb!J16+Mar!J16)+(Apr!P16+May!P16+Jun!P16+Jul!P16+Aug!P16+Sep!P16+Oct!P16+Nov!P16+Dec!P16+Jan!P16+Feb!P16+Mar!P16),0) -> 0 | Q17: =J17-K17-O17-P17 -> 0 | T17: Materials | U17: Registered | V17: 28
A18: =+A17+1 -> 2 | B18: =Yearly!B17 -> 0 | C18: =Yearly!C17 -> 0 | D18: =Yearly!D17 -> 0 | E18: =Yearly!E17 -> 0 | F18: =Yearly!F17 -> 0 | G18: =Yearly!G17 -> 0 | H18: =Yearly!H17 -> 0 | K18: =Apr!P17+May!P17+Jun!P17+Jul!P17+Aug!P17+Sep!P17+Oct!P17+Nov!P17+Dec!P17+Jan!P17+Feb!P17+Mar!P17 -> 0 | L18: =IF(H18="Exempt", (Apr!Q17+May!Q17+Jun!Q17+Jul!Q17+Aug!Q17+Sep!Q17+Oct!Q17+Nov!Q17+Dec!Q17+Jan!Q17+Feb!Q17+Mar!Q17)+(Apr!P17+May!P17+Jun!P17+Jul!P17+Aug!P17+Sep!P17+Oct!P17+Nov!P17+Dec!P17+Jan!P17+Feb!P17+Mar!P17),0) -> 0 | M18: =IF(E18="Composition", (Apr!Q17+May!Q17+Jun!Q17+Jul!Q17+Aug!Q17+Sep!Q17+Oct!Q17+Nov!Q17+Dec!Q17+Jan!Q17+Feb!Q17+Mar!Q17)+(Apr!P17+May!P17+Jun!P17+Jul!P17+Aug!P17+Sep!P17+Oct!P17+Nov!P17+Dec!P17+Jan!P17+Feb!P17+Mar!P17),0) -> 0 | N18: =IF(E18="Registered", (Apr!J17+May!J17+Jun!J17+Jul!J17+Aug!J17+Sep!J17+Oct!J17+Nov!J17+Dec!J17+Jan!J17+Feb!J17+Mar!J17),0) -> 0 | O18: =SUM(L18:N18) -> 0 | P18: =IF(E18="Un-registered", (Apr!J17+May!J17+Jun!J17+Jul!J17+Aug!J17+Sep!J17+Oct!J17+Nov!J17+Dec!J17+Jan!J17+Feb!J17+Mar!J17)+(Apr!P17+May!P17+Jun!P17+Jul!P17+Aug!P17+Sep!P17+Oct!P17+Nov!P17+Dec!P17+Jan!P17+Feb!P17+Mar!P17),0) -> 0 | Q18: =J18-K18-O18-P18 -> 0 | T18: Services | U18: Un-registered | V18: 18
A19: =+A18+1 -> 3 | B19: =Yearly!B18 -> 0 | C19: =Yearly!C18 -> 0 | D19: =Yearly!D18 -> 0 | E19: =Yearly!E18 -> 0 | F19: =Yearly!F18 -> 0 | G19: =Yearly!G18 -> 0 | H19: =Yearly!H18 -> 0 | K19: =Apr!P18+May!P18+Jun!P18+Jul!P18+Aug!P18+Sep!P18+Oct!P18+Nov!P18+Dec!P18+Jan!P18+Feb!P18+Mar!P18 -> 0 | L19: =IF(H19="Exempt", (Apr!Q18+May!Q18+Jun!Q18+Jul!Q18+Aug!Q18+Sep!Q18+Oct!Q18+Nov!Q18+Dec!Q18+Jan!Q18+Feb!Q18+Mar!Q18)+(Apr!P18+May!P18+Jun!P18+Jul!P18+Aug!P18+Sep!P18+Oct!P18+Nov!P18+Dec!P18+Jan!P18+Feb!P18+Mar!P18),0) -> 0 | M19: =IF(E19="Composition", (Apr!Q18+May!Q18+Jun!Q18+Jul!Q18+Aug!Q18+Sep!Q18+Oct!Q18+Nov!Q18+Dec!Q18+Jan!Q18+Feb!Q18+Mar!Q18)+(Apr!P18+May!P18+Jun!P18+Jul!P18+Aug!P18+Sep!P18+Oct!P18+Nov!P18+Dec!P18+Jan!P18+Feb!P18+Mar!P18),0) -> 0 | N19: =IF(E19="Registered", (Apr!J18+May!J18+Jun!J18+Jul!J18+Aug!J18+Sep!J18+Oct!J18+Nov!J18+Dec!J18+Jan!J18+Feb!J18+Mar!J18),0) -> 0 | O19: =SUM(L19:N19) -> 0 | P19: =IF(E19="Un-registered", (Apr!J18+May!J18+Jun!J18+Jul!J18+Aug!J18+Sep!J18+Oct!J18+Nov!J18+Dec!J18+Jan!J18+Feb!J18+Mar!J18)+(Apr!P18+May!P18+Jun!P18+Jul!P18+Aug!P18+Sep!P18+Oct!P18+Nov!P18+Dec!P18+Jan!P18+Feb!P18+Mar!P18),0) -> 0 | Q19: =J19-K19-O19-P19 -> 0 | T19: Capital Goods | U19: Composition | V19: 12
A20: =+A19+1 -> 4 | B20: =Yearly!B19 -> 0 | C20: =Yearly!C19 -> 0 | D20: =Yearly!D19 -> 0 | E20: =Yearly!E19 -> 0 | F20: =Yearly!F19 -> 0 | G20: =Yearly!G19 -> 0 | H20: =Yearly!H19 -> 0 | K20: =Apr!P19+May!P19+Jun!P19+Jul!P19+Aug!P19+Sep!P19+Oct!P19+Nov!P19+Dec!P19+Jan!P19+Feb!P19+Mar!P19 -> 0 | L20: =IF(H20="Exempt", (Apr!Q19+May!Q19+Jun!Q19+Jul!Q19+Aug!Q19+Sep!Q19+Oct!Q19+Nov!Q19+Dec!Q19+Jan!Q19+Feb!Q19+Mar!Q19)+(Apr!P19+May!P19+Jun!P19+Jul!P19+Aug!P19+Sep!P19+Oct!P19+Nov!P19+Dec!P19+Jan!P19+Feb!P19+Mar!P19),0) -> 0 | M20: =IF(E20="Composition", (Apr!Q19+May!Q19+Jun!Q19+Jul!Q19+Aug!Q19+Sep!Q19+Oct!Q19+Nov!Q19+Dec!Q19+Jan!Q19+Feb!Q19+Mar!Q19)+(Apr!P19+May!P19+Jun!P19+Jul!P19+Aug!P19+Sep!P19+Oct!P19+Nov!P19+Dec!P19+Jan!P19+Feb!P19+Mar!P19),0) -> 0 | N20: =IF(E20="Registered", (Apr!J19+May!J19+Jun!J19+Jul!J19+Aug!J19+Sep!J19+Oct!J19+Nov!J19+Dec!J19+Jan!J19+Feb!J19+Mar!J19),0) -> 0 | O20: =SUM(L20:N20) -> 0 | P20: =IF(E20="Un-registered", (Apr!J19+May!J19+Jun!J19+Jul!J19+Aug!J19+Sep!J19+Oct!J19+Nov!J19+Dec!J19+Jan!J19+Feb!J19+Mar!J19)+(Apr!P19+May!P19+Jun!P19+Jul!P19+Aug!P19+Sep!P19+Oct!P19+Nov!P19+Dec!P19+Jan!P19+Feb!P19+Mar!P19),0) -> 0 | Q20: =J20-K20-O20-P20 -> 0 | T20: RCM | U20: Others | V20: 5
A21: =+A20+1 -> 5 | B21: =Yearly!B20 -> 0 | C21: =Yearly!C20 -> 0 | D21: =Yearly!D20 -> 0 | E21: =Yearly!E20 -> 0 | F21: =Yearly!F20 -> 0 | G21: =Yearly!G20 -> 0 | H21: =Yearly!H20 -> 0 | K21: =Apr!P20+May!P20+Jun!P20+Jul!P20+Aug!P20+Sep!P20+Oct!P20+Nov!P20+Dec!P20+Jan!P20+Feb!P20+Mar!P20 -> 0 | L21: =IF(H21="Exempt", (Apr!Q20+May!Q20+Jun!Q20+Jul!Q20+Aug!Q20+Sep!Q20+Oct!Q20+Nov!Q20+Dec!Q20+Jan!Q20+Feb!Q20+Mar!Q20)+(Apr!P20+May!P20+Jun!P20+Jul!P20+Aug!P20+Sep!P20+Oct!P20+Nov!P20+Dec!P20+Jan!P20+Feb!P20+Mar!P20),0) -> 0 | M21: =IF(E21="Composition", (Apr!Q20+May!Q20+Jun!Q20+Jul!Q20+Aug!Q20+Sep!Q20+Oct!Q20+Nov!Q20+Dec!Q20+Jan!Q20+Feb!Q20+Mar!Q20)+(Apr!P20+May!P20+Jun!P20+Jul!P20+Aug!P20+Sep!P20+Oct!P20+Nov!P20+Dec!P20+Jan!P20+Feb!P20+Mar!P20),0) -> 0 | N21: =IF(E21="Registered", (Apr!J20+May!J20+Jun!J20+Jul!J20+Aug!J20+Sep!J20+Oct!J20+Nov!J20+Dec!J20+Jan!J20+Feb!J20+Mar!J20),0) -> 0 | O21: =SUM(L21:N21) -> 0 | P21: =IF(E21="Un-registered", (Apr!J20+May!J20+Jun!J20+Jul!J20+Aug!J20+Sep!J20+Oct!J20+Nov!J20+Dec!J20+Jan!J20+Feb!J20+Mar!J20)+(Apr!P20+May!P20+Jun!P20+Jul!P20+Aug!P20+Sep!P20+Oct!P20+Nov!P20+Dec!P20+Jan!P20+Feb!P20+Mar!P20),0) -> 0 | Q21: =J21-K21-O21-P21 -> 0 | T21: Others | V21: 3
A22: =+A21+1 -> 6 | B22: =Yearly!B21 -> 0 | C22: =Yearly!C21 -> 0 | D22: =Yearly!D21 -> 0 | E22: =Yearly!E21 -> 0 | F22: =Yearly!F21 -> 0 | G22: =Yearly!G21 -> 0 | H22: =Yearly!H21 -> 0 | K22: =Apr!P21+May!P21+Jun!P21+Jul!P21+Aug!P21+Sep!P21+Oct!P21+Nov!P21+Dec!P21+Jan!P21+Feb!P21+Mar!P21 -> 0 | L22: =IF(H22="Exempt", (Apr!Q21+May!Q21+Jun!Q21+Jul!Q21+Aug!Q21+Sep!Q21+Oct!Q21+Nov!Q21+Dec!Q21+Jan!Q21+Feb!Q21+Mar!Q21)+(Apr!P21+May!P21+Jun!P21+Jul!P21+Aug!P21+Sep!P21+Oct!P21+Nov!P21+Dec!P21+Jan!P21+Feb!P21+Mar!P21),0) -> 0 | M22: =IF(E22="Composition", (Apr!Q21+May!Q21+Jun!Q21+Jul!Q21+Aug!Q21+Sep!Q21+Oct!Q21+Nov!Q21+Dec!Q21+Jan!Q21+Feb!Q21+Mar!Q21)+(Apr!P21+May!P21+Jun!P21+Jul!P21+Aug!P21+Sep!P21+Oct!P21+Nov!P21+Dec!P21+Jan!P21+Feb!P21+Mar!P21),0) -> 0 | N22: =IF(E22="Registered", (Apr!J21+May!J21+Jun!J21+Jul!J21+Aug!J21+Sep!J21+Oct!J21+Nov!J21+Dec!J21+Jan!J21+Feb!J21+Mar!J21),0) -> 0 | O22: =SUM(L22:N22) -> 0 | P22: =IF(E22="Un-registered", (Apr!J21+May!J21+Jun!J21+Jul!J21+Aug!J21+Sep!J21+Oct!J21+Nov!J21+Dec!J21+Jan!J21+Feb!J21+Mar!J21)+(Apr!P21+May!P21+Jun!P21+Jul!P21+Aug!P21+Sep!P21+Oct!P21+Nov!P21+Dec!P21+Jan!P21+Feb!P21+Mar!P21),0) -> 0 | Q22: =J22-K22-O22-P22 -> 0 | V22: 0.25
A23: =+A22+1 -> 7 | B23: =Yearly!B22 -> 0 | C23: =Yearly!C22 -> 0 | D23: =Yearly!D22 -> 0 | E23: =Yearly!E22 -> 0 | F23: =Yearly!F22 -> 0 | G23: =Yearly!G22 -> 0 | H23: =Yearly!H22 -> 0 | K23: =Apr!P22+May!P22+Jun!P22+Jul!P22+Aug!P22+Sep!P22+Oct!P22+Nov!P22+Dec!P22+Jan!P22+Feb!P22+Mar!P22 -> 0 | L23: =IF(H23="Exempt", (Apr!Q22+May!Q22+Jun!Q22+Jul!Q22+Aug!Q22+Sep!Q22+Oct!Q22+Nov!Q22+Dec!Q22+Jan!Q22+Feb!Q22+Mar!Q22)+(Apr!P22+May!P22+Jun!P22+Jul!P22+Aug!P22+Sep!P22+Oct!P22+Nov!P22+Dec!P22+Jan!P22+Feb!P22+Mar!P22),0) -> 0 | M23: =IF(E23="Composition", (Apr!Q22+May!Q22+Jun!Q22+Jul!Q22+Aug!Q22+Sep!Q22+Oct!Q22+Nov!Q22+Dec!Q22+Jan!Q22+Feb!Q22+Mar!Q22)+(Apr!P22+May!P22+Jun!P22+Jul!P22+Aug!P22+Sep!P22+Oct!P22+Nov!P22+Dec!P22+Jan!P22+Feb!P22+Mar!P22),0) -> 0 | N23: =IF(E23="Registered", (Apr!J22+May!J22+Jun!J22+Jul!J22+Aug!J22+Sep!J22+Oct!J22+Nov!J22+Dec!J22+Jan!J22+Feb!J22+Mar!J22),0) -> 0 | O23: =SUM(L23:N23) -> 0 | P23: =IF(E23="Un-registered", (Apr!J22+May!J22+Jun!J22+Jul!J22+Aug!J22+Sep!J22+Oct!J22+Nov!J22+Dec!J22+Jan!J22+Feb!J22+Mar!J22)+(Apr!P22+May!P22+Jun!P22+Jul!P22+Aug!P22+Sep!P22+Oct!P22+Nov!P22+Dec!P22+Jan!P22+Feb!P22+Mar!P22),0) -> 0 | Q23: =J23-K23-O23-P23 -> 0 | V23: 0.1
A24: =+A23+1 -> 8 | B24: =Yearly!B23 -> 0 | C24: =Yearly!C23 -> 0 | D24: =Yearly!D23 -> 0 | E24: =Yearly!E23 -> 0 | F24: =Yearly!F23 -> 0 | G24: =Yearly!G23 -> 0 | H24: =Yearly!H23 -> 0 | K24: =Apr!P23+May!P23+Jun!P23+Jul!P23+Aug!P23+Sep!P23+Oct!P23+Nov!P23+Dec!P23+Jan!P23+Feb!P23+Mar!P23 -> 0 | L24: =IF(H24="Exempt", (Apr!Q23+May!Q23+Jun!Q23+Jul!Q23+Aug!Q23+Sep!Q23+Oct!Q23+Nov!Q23+Dec!Q23+Jan!Q23+Feb!Q23+Mar!Q23)+(Apr!P23+May!P23+Jun!P23+Jul!P23+Aug!P23+Sep!P23+Oct!P23+Nov!P23+Dec!P23+Jan!P23+Feb!P23+Mar!P23),0) -> 0 | M24: =IF(E24="Composition", (Apr!Q23+May!Q23+Jun!Q23+Jul!Q23+Aug!Q23+Sep!Q23+Oct!Q23+Nov!Q23+Dec!Q23+Jan!Q23+Feb!Q23+Mar!Q23)+(Apr!P23+May!P23+Jun!P23+Jul!P23+Aug!P23+Sep!P23+Oct!P23+Nov!P23+Dec!P23+Jan!P23+Feb!P23+Mar!P23),0) -> 0 | N24: =IF(E24="Registered", (Apr!J23+May!J23+Jun!J23+Jul!J23+Aug!J23+Sep!J23+Oct!J23+Nov!J23+Dec!J23+Jan!J23+Feb!J23+Mar!J23),0) -> 0 | O24: =SUM(L24:N24) -> 0 | P24: =IF(E24="Un-registered", (Apr!J23+May!J23+Jun!J23+Jul!J23+Aug!J23+Sep!J23+Oct!J23+Nov!J23+Dec!J23+Jan!J23+Feb!J23+Mar!J23)+(Apr!P23+May!P23+Jun!P23+Jul!P23+Aug!P23+Sep!P23+Oct!P23+Nov!P23+Dec!P23+Jan!P23+Feb!P23+Mar!P23),0) -> 0 | Q24: =J24-K24-O24-P24 -> 0 | V24: 0
A25: =+A24+1 -> 9 | B25: =Yearly!B24 -> 0 | C25: =Yearly!C24 -> 0 | D25: =Yearly!D24 -> 0 | E25: =Yearly!E24 -> 0 | F25: =Yearly!F24 -> 0 | G25: =Yearly!G24 -> 0 | H25: =Yearly!H24 -> 0 | K25: =Apr!P24+May!P24+Jun!P24+Jul!P24+Aug!P24+Sep!P24+Oct!P24+Nov!P24+Dec!P24+Jan!P24+Feb!P24+Mar!P24 -> 0 | L25: =IF(H25="Exempt", (Apr!Q24+May!Q24+Jun!Q24+Jul!Q24+Aug!Q24+Sep!Q24+Oct!Q24+Nov!Q24+Dec!Q24+Jan!Q24+Feb!Q24+Mar!Q24)+(Apr!P24+May!P24+Jun!P24+Jul!P24+Aug!P24+Sep!P24+Oct!P24+Nov!P24+Dec!P24+Jan!P24+Feb!P24+Mar!P24),0) -> 0 | M25: =IF(E25="Composition", (Apr!Q24+May!Q24+Jun!Q24+Jul!Q24+Aug!Q24+Sep!Q24+Oct!Q24+Nov!Q24+Dec!Q24+Jan!Q24+Feb!Q24+Mar!Q24)+(Apr!P24+May!P24+Jun!P24+Jul!P24+Aug!P24+Sep!P24+Oct!P24+Nov!P24+Dec!P24+Jan!P24+Feb!P24+Mar!P24),0) -> 0 | N25: =IF(E25="Registered", (Apr!J24+May!J24+Jun!J24+Jul!J24+Aug!J24+Sep!J24+Oct!J24+Nov!J24+Dec!J24+Jan!J24+Feb!J24+Mar!J24),0) -> 0 | O25: =SUM(L25:N25) -> 0 | P25: =IF(E25="Un-registered", (Apr!J24+May!J24+Jun!J24+Jul!J24+Aug!J24+Sep!J24+Oct!J24+Nov!J24+Dec!J24+Jan!J24+Feb!J24+Mar!J24)+(Apr!P24+May!P24+Jun!P24+Jul!P24+Aug!P24+Sep!P24+Oct!P24+Nov!P24+Dec!P24+Jan!P24+Feb!P24+Mar!P24),0) -> 0 | Q25: =J25-K25-O25-P25 -> 0
A26: =+A25+1 -> 10 | B26: =Yearly!B25 -> 0 | C26: =Yearly!C25 -> 0 | D26: =Yearly!D25 -> 0 | E26: =Yearly!E25 -> 0 | F26: =Yearly!F25 -> 0 | G26: =Yearly!G25 -> 0 | H26: =Yearly!H25 -> 0 | K26: =Apr!P25+May!P25+Jun!P25+Jul!P25+Aug!P25+Sep!P25+Oct!P25+Nov!P25+Dec!P25+Jan!P25+Feb!P25+Mar!P25 -> 0 | L26: =IF(H26="Exempt", (Apr!Q25+May!Q25+Jun!Q25+Jul!Q25+Aug!Q25+Sep!Q25+Oct!Q25+Nov!Q25+Dec!Q25+Jan!Q25+Feb!Q25+Mar!Q25)+(Apr!P25+May!P25+Jun!P25+Jul!P25+Aug!P25+Sep!P25+Oct!P25+Nov!P25+Dec!P25+Jan!P25+Feb!P25+Mar!P25),0) -> 0 | M26: =IF(E26="Composition", (Apr!Q25+May!Q25+Jun!Q25+Jul!Q25+Aug!Q25+Sep!Q25+Oct!Q25+Nov!Q25+Dec!Q25+Jan!Q25+Feb!Q25+Mar!Q25)+(Apr!P25+May!P25+Jun!P25+Jul!P25+Aug!P25+Sep!P25+Oct!P25+Nov!P25+Dec!P25+Jan!P25+Feb!P25+Mar!P25),0) -> 0 | N26: =IF(E26="Registered", (Apr!J25+May!J25+Jun!J25+Jul!J25+Aug!J25+Sep!J25+Oct!J25+Nov!J25+Dec!J25+Jan!J25+Feb!J25+Mar!J25),0) -> 0 | O26: =SUM(L26:N26) -> 0 | P26: =IF(E26="Un-registered", (Apr!J25+May!J25+Jun!J25+Jul!J25+Aug!J25+Sep!J25+Oct!J25+Nov!J25+Dec!J25+Jan!J25+Feb!J25+Mar!J25)+(Apr!P25+May!P25+Jun!P25+Jul!P25+Aug!P25+Sep!P25+Oct!P25+Nov!P25+Dec!P25+Jan!P25+Feb!P25+Mar!P25),0) -> 0 | Q26: =J26-K26-O26-P26 -> 0
A27: =+A26+1 -> 11 | B27: =Yearly!B26 -> 0 | C27: =Yearly!C26 -> 0 | D27: =Yearly!D26 -> 0 | E27: =Yearly!E26 -> 0 | F27: =Yearly!F26 -> 0 | G27: =Yearly!G26 -> 0 | H27: =Yearly!H26 -> 0 | K27: =Apr!P26+May!P26+Jun!P26+Jul!P26+Aug!P26+Sep!P26+Oct!P26+Nov!P26+Dec!P26+Jan!P26+Feb!P26+Mar!P26 -> 0 | L27: =IF(H27="Exempt", (Apr!Q26+May!Q26+Jun!Q26+Jul!Q26+Aug!Q26+Sep!Q26+Oct!Q26+Nov!Q26+Dec!Q26+Jan!Q26+Feb!Q26+Mar!Q26)+(Apr!P26+May!P26+Jun!P26+Jul!P26+Aug!P26+Sep!P26+Oct!P26+Nov!P26+Dec!P26+Jan!P26+Feb!P26+Mar!P26),0) -> 0 | M27: =IF(E27="Composition", (Apr!Q26+May!Q26+Jun!Q26+Jul!Q26+Aug!Q26+Sep!Q26+Oct!Q26+Nov!Q26+Dec!Q26+Jan!Q26+Feb!Q26+Mar!Q26)+(Apr!P26+May!P26+Jun!P26+Jul!P26+Aug!P26+Sep!P26+Oct!P26+Nov!P26+Dec!P26+Jan!P26+Feb!P26+Mar!P26),0) -> 0 | N27: =IF(E27="Registered", (Apr!J26+May!J26+Jun!J26+Jul!J26+Aug!J26+Sep!J26+Oct!J26+Nov!J26+Dec!J26+Jan!J26+Feb!J26+Mar!J26),0) -> 0 | O27: =SUM(L27:N27) -> 0 | P27: =IF(E27="Un-registered", (Apr!J26+May!J26+Jun!J26+Jul!J26+Aug!J26+Sep!J26+Oct!J26+Nov!J26+Dec!J26+Jan!J26+Feb!J26+Mar!J26)+(Apr!P26+May!P26+Jun!P26+Jul!P26+Aug!P26+Sep!P26+Oct!P26+Nov!P26+Dec!P26+Jan!P26+Feb!P26+Mar!P26),0) -> 0 | Q27: =J27-K27-O27-P27 -> 0
A28: =+A27+1 -> 12 | B28: =Yearly!B27 -> 0 | C28: =Yearly!C27 -> 0 | D28: =Yearly!D27 -> 0 | E28: =Yearly!E27 -> 0 | F28: =Yearly!F27 -> 0 | G28: =Yearly!G27 -> 0 | H28: =Yearly!H27 -> 0 | K28: =Apr!P27+May!P27+Jun!P27+Jul!P27+Aug!P27+Sep!P27+Oct!P27+Nov!P27+Dec!P27+Jan!P27+Feb!P27+Mar!P27 -> 0 | L28: =IF(H28="Exempt", (Apr!Q27+May!Q27+Jun!Q27+Jul!Q27+Aug!Q27+Sep!Q27+Oct!Q27+Nov!Q27+Dec!Q27+Jan!Q27+Feb!Q27+Mar!Q27)+(Apr!P27+May!P27+Jun!P27+Jul!P27+Aug!P27+Sep!P27+Oct!P27+Nov!P27+Dec!P27+Jan!P27+Feb!P27+Mar!P27),0) -> 0 | M28: =IF(E28="Composition", (Apr!Q27+May!Q27+Jun!Q27+Jul!Q27+Aug!Q27+Sep!Q27+Oct!Q27+Nov!Q27+Dec!Q27+Jan!Q27+Feb!Q27+Mar!Q27)+(Apr!P27+May!P27+Jun!P27+Jul!P27+Aug!P27+Sep!P27+Oct!P27+Nov!P27+Dec!P27+Jan!P27+Feb!P27+Mar!P27),0) -> 0 | N28: =IF(E28="Registered", (Apr!J27+May!J27+Jun!J27+Jul!J27+Aug!J27+Sep!J27+Oct!J27+Nov!J27+Dec!J27+Jan!J27+Feb!J27+Mar!J27),0) -> 0 | O28: =SUM(L28:N28) -> 0 | P28: =IF(E28="Un-registered", (Apr!J27+May!J27+Jun!J27+Jul!J27+Aug!J27+Sep!J27+Oct!J27+Nov!J27+Dec!J27+Jan!J27+Feb!J27+Mar!J27)+(Apr!P27+May!P27+Jun!P27+Jul!P27+Aug!P27+Sep!P27+Oct!P27+Nov!P27+Dec!P27+Jan!P27+Feb!P27+Mar!P27),0) -> 0 | Q28: =J28-K28-O28-P28 -> 0
A29: =+A28+1 -> 13 | B29: =Yearly!B28 -> 0 | C29: =Yearly!C28 -> 0 | D29: =Yearly!D28 -> 0 | E29: =Yearly!E28 -> 0 | F29: =Yearly!F28 -> 0 | G29: =Yearly!G28 -> 0 | H29: =Yearly!H28 -> 0 | K29: =Apr!P28+May!P28+Jun!P28+Jul!P28+Aug!P28+Sep!P28+Oct!P28+Nov!P28+Dec!P28+Jan!P28+Feb!P28+Mar!P28 -> 0 | L29: =IF(H29="Exempt", (Apr!Q28+May!Q28+Jun!Q28+Jul!Q28+Aug!Q28+Sep!Q28+Oct!Q28+Nov!Q28+Dec!Q28+Jan!Q28+Feb!Q28+Mar!Q28)+(Apr!P28+May!P28+Jun!P28+Jul!P28+Aug!P28+Sep!P28+Oct!P28+Nov!P28+Dec!P28+Jan!P28+Feb!P28+Mar!P28),0) -> 0 | M29: =IF(E29="Composition", (Apr!Q28+May!Q28+Jun!Q28+Jul!Q28+Aug!Q28+Sep!Q28+Oct!Q28+Nov!Q28+Dec!Q28+Jan!Q28+Feb!Q28+Mar!Q28)+(Apr!P28+May!P28+Jun!P28+Jul!P28+Aug!P28+Sep!P28+Oct!P28+Nov!P28+Dec!P28+Jan!P28+Feb!P28+Mar!P28),0) -> 0 | N29: =IF(E29="Registered", (Apr!J28+May!J28+Jun!J28+Jul!J28+Aug!J28+Sep!J28+Oct!J28+Nov!J28+Dec!J28+Jan!J28+Feb!J28+Mar!J28),0) -> 0 | O29: =SUM(L29:N29) -> 0 | P29: =IF(E29="Un-registered", (Apr!J28+May!J28+Jun!J28+Jul!J28+Aug!J28+Sep!J28+Oct!J28+Nov!J28+Dec!J28+Jan!J28+Feb!J28+Mar!J28)+(Apr!P28+May!P28+Jun!P28+Jul!P28+Aug!P28+Sep!P28+Oct!P28+Nov!P28+Dec!P28+Jan!P28+Feb!P28+Mar!P28),0) -> 0 | Q29: =J29-K29-O29-P29 -> 0
A30: =+A29+1 -> 14 | B30: =Yearly!B29 -> 0 | C30: =Yearly!C29 -> 0 | D30: =Yearly!D29 -> 0 | E30: =Yearly!E29 -> 0 | F30: =Yearly!F29 -> 0 | G30: =Yearly!G29 -> 0 | H30: =Yearly!H29 -> 0 | K30: =Apr!P29+May!P29+Jun!P29+Jul!P29+Aug!P29+Sep!P29+Oct!P29+Nov!P29+Dec!P29+Jan!P29+Feb!P29+Mar!P29 -> 0 | L30: =IF(H30="Exempt", (Apr!Q29+May!Q29+Jun!Q29+Jul!Q29+Aug!Q29+Sep!Q29+Oct!Q29+Nov!Q29+Dec!Q29+Jan!Q29+Feb!Q29+Mar!Q29)+(Apr!P29+May!P29+Jun!P29+Jul!P29+Aug!P29+Sep!P29+Oct!P29+Nov!P29+Dec!P29+Jan!P29+Feb!P29+Mar!P29),0) -> 0 | M30: =IF(E30="Composition", (Apr!Q29+May!Q29+Jun!Q29+Jul!Q29+Aug!Q29+Sep!Q29+Oct!Q29+Nov!Q29+Dec!Q29+Jan!Q29+Feb!Q29+Mar!Q29)+(Apr!P29+May!P29+Jun!P29+Jul!P29+Aug!P29+Sep!P29+Oct!P29+Nov!P29+Dec!P29+Jan!P29+Feb!P29+Mar!P29),0) -> 0 | N30: =IF(E30="Registered", (Apr!J29+May!J29+Jun!J29+Jul!J29+Aug!J29+Sep!J29+Oct!J29+Nov!J29+Dec!J29+Jan!J29+Feb!J29+Mar!J29),0) -> 0 | O30: =SUM(L30:N30) -> 0 | P30: =IF(E30="Un-registered", (Apr!J29+May!J29+Jun!J29+Jul!J29+Aug!J29+Sep!J29+Oct!J29+Nov!J29+Dec!J29+Jan!J29+Feb!J29+Mar!J29)+(Apr!P29+May!P29+Jun!P29+Jul!P29+Aug!P29+Sep!P29+Oct!P29+Nov!P29+Dec!P29+Jan!P29+Feb!P29+Mar!P29),0) -> 0 | Q30: =J30-K30-O30-P30 -> 0
A31: =+A30+1 -> 15 | B31: =Yearly!B30 -> 0 | C31: =Yearly!C30 -> 0 | D31: =Yearly!D30 -> 0 | E31: =Yearly!E30 -> 0 | F31: =Yearly!F30 -> 0 | G31: =Yearly!G30 -> 0 | H31: =Yearly!H30 -> 0 | K31: =Apr!P30+May!P30+Jun!P30+Jul!P30+Aug!P30+Sep!P30+Oct!P30+Nov!P30+Dec!P30+Jan!P30+Feb!P30+Mar!P30 -> 0 | L31: =IF(H31="Exempt", (Apr!Q30+May!Q30+Jun!Q30+Jul!Q30+Aug!Q30+Sep!Q30+Oct!Q30+Nov!Q30+Dec!Q30+Jan!Q30+Feb!Q30+Mar!Q30)+(Apr!P30+May!P30+Jun!P30+Jul!P30+Aug!P30+Sep!P30+Oct!P30+Nov!P30+Dec!P30+Jan!P30+Feb!P30+Mar!P30),0) -> 0 | M31: =IF(E31="Composition", (Apr!Q30+May!Q30+Jun!Q30+Jul!Q30+Aug!Q30+Sep!Q30+Oct!Q30+Nov!Q30+Dec!Q30+Jan!Q30+Feb!Q30+Mar!Q30)+(Apr!P30+May!P30+Jun!P30+Jul!P30+Aug!P30+Sep!P30+Oct!P30+Nov!P30+Dec!P30+Jan!P30+Feb!P30+Mar!P30),0) -> 0 | N31: =IF(E31="Registered", (Apr!J30+May!J30+Jun!J30+Jul!J30+Aug!J30+Sep!J30+Oct!J30+Nov!J30+Dec!J30+Jan!J30+Feb!J30+Mar!J30),0) -> 0 | O31: =SUM(L31:N31) -> 0 | P31: =IF(E31="Un-registered", (Apr!J30+May!J30+Jun!J30+Jul!J30+Aug!J30+Sep!J30+Oct!J30+Nov!J30+Dec!J30+Jan!J30+Feb!J30+Mar!J30)+(Apr!P30+May!P30+Jun!P30+Jul!P30+Aug!P30+Sep!P30+Oct!P30+Nov!P30+Dec!P30+Jan!P30+Feb!P30+Mar!P30),0) -> 0 | Q31: =J31-K31-O31-P31 -> 0
A32: =+A31+1 -> 16 | B32: =Yearly!B31 -> 0 | C32: =Yearly!C31 -> 0 | D32: =Yearly!D31 -> 0 | E32: =Yearly!E31 -> 0 | F32: =Yearly!F31 -> 0 | G32: =Yearly!G31 -> 0 | H32: =Yearly!H31 -> 0 | K32: =Apr!P31+May!P31+Jun!P31+Jul!P31+Aug!P31+Sep!P31+Oct!P31+Nov!P31+Dec!P31+Jan!P31+Feb!P31+Mar!P31 -> 0 | L32: =IF(H32="Exempt", (Apr!Q31+May!Q31+Jun!Q31+Jul!Q31+Aug!Q31+Sep!Q31+Oct!Q31+Nov!Q31+Dec!Q31+Jan!Q31+Feb!Q31+Mar!Q31)+(Apr!P31+May!P31+Jun!P31+Jul!P31+Aug!P31+Sep!P31+Oct!P31+Nov!P31+Dec!P31+Jan!P31+Feb!P31+Mar!P31),0) -> 0 | M32: =IF(E32="Composition", (Apr!Q31+May!Q31+Jun!Q31+Jul!Q31+Aug!Q31+Sep!Q31+Oct!Q31+Nov!Q31+Dec!Q31+Jan!Q31+Feb!Q31+Mar!Q31)+(Apr!P31+May!P31+Jun!P31+Jul!P31+Aug!P31+Sep!P31+Oct!P31+Nov!P31+Dec!P31+Jan!P31+Feb!P31+Mar!P31),0) -> 0 | N32: =IF(E32="Registered", (Apr!J31+May!J31+Jun!J31+Jul!J31+Aug!J31+Sep!J31+Oct!J31+Nov!J31+Dec!J31+Jan!J31+Feb!J31+Mar!J31),0) -> 0 | O32: =SUM(L32:N32) -> 0 | P32: =IF(E32="Un-registered", (Apr!J31+May!J31+Jun!J31+Jul!J31+Aug!J31+Sep!J31+Oct!J31+Nov!J31+Dec!J31+Jan!J31+Feb!J31+Mar!J31)+(Apr!P31+May!P31+Jun!P31+Jul!P31+Aug!P31+Sep!P31+Oct!P31+Nov!P31+Dec!P31+Jan!P31+Feb!P31+Mar!P31),0) -> 0 | Q32: =J32-K32-O32-P32 -> 0
A33: =+A32+1 -> 17 | B33: =Yearly!B32 -> 0 | C33: =Yearly!C32 -> 0 | D33: =Yearly!D32 -> 0 | E33: =Yearly!E32 -> 0 | F33: =Yearly!F32 -> 0 | G33: =Yearly!G32 -> 0 | H33: =Yearly!H32 -> 0 | K33: =Apr!P32+May!P32+Jun!P32+Jul!P32+Aug!P32+Sep!P32+Oct!P32+Nov!P32+Dec!P32+Jan!P32+Feb!P32+Mar!P32 -> 0 | L33: =IF(H33="Exempt", (Apr!Q32+May!Q32+Jun!Q32+Jul!Q32+Aug!Q32+Sep!Q32+Oct!Q32+Nov!Q32+Dec!Q32+Jan!Q32+Feb!Q32+Mar!Q32)+(Apr!P32+May!P32+Jun!P32+Jul!P32+Aug!P32+Sep!P32+Oct!P32+Nov!P32+Dec!P32+Jan!P32+Feb!P32+Mar!P32),0) -> 0 | M33: =IF(E33="Composition", (Apr!Q32+May!Q32+Jun!Q32+Jul!Q32+Aug!Q32+Sep!Q32+Oct!Q32+Nov!Q32+Dec!Q32+Jan!Q32+Feb!Q32+Mar!Q32)+(Apr!P32+May!P32+Jun!P32+Jul!P32+Aug!P32+Sep!P32+Oct!P32+Nov!P32+Dec!P32+Jan!P32+Feb!P32+Mar!P32),0) -> 0 | N33: =IF(E33="Registered", (Apr!J32+May!J32+Jun!J32+Jul!J32+Aug!J32+Sep!J32+Oct!J32+Nov!J32+Dec!J32+Jan!J32+Feb!J32+Mar!J32),0) -> 0 | O33: =SUM(L33:N33) -> 0 | P33: =IF(E33="Un-registered", (Apr!J32+May!J32+Jun!J32+Jul!J32+Aug!J32+Sep!J32+Oct!J32+Nov!J32+Dec!J32+Jan!J32+Feb!J32+Mar!J32)+(Apr!P32+May!P32+Jun!P32+Jul!P32+Aug!P32+Sep!P32+Oct!P32+Nov!P32+Dec!P32+Jan!P32+Feb!P32+Mar!P32),0) -> 0 | Q33: =J33-K33-O33-P33 -> 0
A34: =+A33+1 -> 18 | B34: =Yearly!B33 -> 0 | C34: =Yearly!C33 -> 0 | D34: =Yearly!D33 -> 0 | E34: =Yearly!E33 -> 0 | F34: =Yearly!F33 -> 0 | G34: =Yearly!G33 -> 0 | H34: =Yearly!H33 -> 0 | K34: =Apr!P33+May!P33+Jun!P33+Jul!P33+Aug!P33+Sep!P33+Oct!P33+Nov!P33+Dec!P33+Jan!P33+Feb!P33+Mar!P33 -> 0 | L34: =IF(H34="Exempt", (Apr!Q33+May!Q33+Jun!Q33+Jul!Q33+Aug!Q33+Sep!Q33+Oct!Q33+Nov!Q33+Dec!Q33+Jan!Q33+Feb!Q33+Mar!Q33)+(Apr!P33+May!P33+Jun!P33+Jul!P33+Aug!P33+Sep!P33+Oct!P33+Nov!P33+Dec!P33+Jan!P33+Feb!P33+Mar!P33),0) -> 0 | M34: =IF(E34="Composition", (Apr!Q33+May!Q33+Jun!Q33+Jul!Q33+Aug!Q33+Sep!Q33+Oct!Q33+Nov!Q33+Dec!Q33+Jan!Q33+Feb!Q33+Mar!Q33)+(Apr!P33+May!P33+Jun!P33+Jul!P33+Aug!P33+Sep!P33+Oct!P33+Nov!P33+Dec!P33+Jan!P33+Feb!P33+Mar!P33),0) -> 0 | N34: =IF(E34="Registered", (Apr!J33+May!J33+Jun!J33+Jul!J33+Aug!J33+Sep!J33+Oct!J33+Nov!J33+Dec!J33+Jan!J33+Feb!J33+Mar!J33),0) -> 0 | O34: =SUM(L34:N34) -> 0 | P34: =IF(E34="Un-registered", (Apr!J33+May!J33+Jun!J33+Jul!J33+Aug!J33+Sep!J33+Oct!J33+Nov!J33+Dec!J33+Jan!J33+Feb!J33+Mar!J33)+(Apr!P33+May!P33+Jun!P33+Jul!P33+Aug!P33+Sep!P33+Oct!P33+Nov!P33+Dec!P33+Jan!P33+Feb!P33+Mar!P33),0) -> 0 | Q34: =J34-K34-O34-P34 -> 0
A35: =+A34+1 -> 19 | B35: =Yearly!B34 -> 0 | C35: =Yearly!C34 -> 0 | D35: =Yearly!D34 -> 0 | E35: =Yearly!E34 -> 0 | F35: =Yearly!F34 -> 0 | G35: =Yearly!G34 -> 0 | H35: =Yearly!H34 -> 0 | K35: =Apr!P34+May!P34+Jun!P34+Jul!P34+Aug!P34+Sep!P34+Oct!P34+Nov!P34+Dec!P34+Jan!P34+Feb!P34+Mar!P34 -> 0 | L35: =IF(H35="Exempt", (Apr!Q34+May!Q34+Jun!Q34+Jul!Q34+Aug!Q34+Sep!Q34+Oct!Q34+Nov!Q34+Dec!Q34+Jan!Q34+Feb!Q34+Mar!Q34)+(Apr!P34+May!P34+Jun!P34+Jul!P34+Aug!P34+Sep!P34+Oct!P34+Nov!P34+Dec!P34+Jan!P34+Feb!P34+Mar!P34),0) -> 0 | M35: =IF(E35="Composition", (Apr!Q34+May!Q34+Jun!Q34+Jul!Q34+Aug!Q34+Sep!Q34+Oct!Q34+Nov!Q34+Dec!Q34+Jan!Q34+Feb!Q34+Mar!Q34)+(Apr!P34+May!P34+Jun!P34+Jul!P34+Aug!P34+Sep!P34+Oct!P34+Nov!P34+Dec!P34+Jan!P34+Feb!P34+Mar!P34),0) -> 0 | N35: =IF(E35="Registered", (Apr!J34+May!J34+Jun!J34+Jul!J34+Aug!J34+Sep!J34+Oct!J34+Nov!J34+Dec!J34+Jan!J34+Feb!J34+Mar!J34),0) -> 0 | O35: =SUM(L35:N35) -> 0 | P35: =IF(E35="Un-registered", (Apr!J34+May!J34+Jun!J34+Jul!J34+Aug!J34+Sep!J34+Oct!J34+Nov!J34+Dec!J34+Jan!J34+Feb!J34+Mar!J34)+(Apr!P34+May!P34+Jun!P34+Jul!P34+Aug!P34+Sep!P34+Oct!P34+Nov!P34+Dec!P34+Jan!P34+Feb!P34+Mar!P34),0) -> 0 | Q35: =J35-K35-O35-P35 -> 0
A36: =+A35+1 -> 20 | B36: =Yearly!B35 -> Sales | C36: =Yearly!C35 -> TRANSPORTER SALES | D36: =Yearly!D35 -> Services | E36: =Yearly!E35 -> Registered | F36: =Yearly!F35 -> RCM Invoice | G36: =Yearly!G35 -> 0 | H36: =Yearly!H35 -> 5 | K36: =Apr!P35+May!P35+Jun!P35+Jul!P35+Aug!P35+Sep!P35+Oct!P35+Nov!P35+Dec!P35+Jan!P35+Feb!P35+Mar!P35 -> 0 | L36: =IF(H36="Exempt", (Apr!Q35+May!Q35+Jun!Q35+Jul!Q35+Aug!Q35+Sep!Q35+Oct!Q35+Nov!Q35+Dec!Q35+Jan!Q35+Feb!Q35+Mar!Q35)+(Apr!P35+May!P35+Jun!P35+Jul!P35+Aug!P35+Sep!P35+Oct!P35+Nov!P35+Dec!P35+Jan!P35+Feb!P35+Mar!P35),0) -> 0 | M36: =IF(E36="Composition", (Apr!Q35+May!Q35+Jun!Q35+Jul!Q35+Aug!Q35+Sep!Q35+Oct!Q35+Nov!Q35+Dec!Q35+Jan!Q35+Feb!Q35+Mar!Q35)+(Apr!P35+May!P35+Jun!P35+Jul!P35+Aug!P35+Sep!P35+Oct!P35+Nov!P35+Dec!P35+Jan!P35+Feb!P35+Mar!P35),0) -> 0 | N36: =IF(E36="Registered", (Apr!J35+May!J35+Jun!J35+Jul!J35+Aug!J35+Sep!J35+Oct!J35+Nov!J35+Dec!J35+Jan!J35+Feb!J35+Mar!J35),0) -> 0 | O36: =SUM(L36:N36) -> 0 | P36: =IF(E36="Un-registered", (Apr!J35+May!J35+Jun!J35+Jul!J35+Aug!J35+Sep!J35+Oct!J35+Nov!J35+Dec!J35+Jan!J35+Feb!J35+Mar!J35)+(Apr!P35+May!P35+Jun!P35+Jul!P35+Aug!P35+Sep!P35+Oct!P35+Nov!P35+Dec!P35+Jan!P35+Feb!P35+Mar!P35),0) -> 0 | Q36: =J36-K36-O36-P36 -> 0
... A515: =+A514+1 -> 499 | B515: =Yearly!B514 -> 0 | C515: =Yearly!C514 -> 0 | D515: =Yearly!D514 -> 0 | E515: =Yearly!E514 -> 0 | F515: =Yearly!F514 -> 0 | G515: =Yearly!G514 -> 0 | H515: =Yearly!H514 -> 0 | K515: =Apr!P514+May!P514+Jun!P514+Jul!P514+Aug!P514+Sep!P514+Oct!P514+Nov!P514+Dec!P514+Jan!P514+Feb!P514+Mar!P514 -> 0 | L515: =IF(H515="Exempt", (Apr!Q514+May!Q514+Jun!Q514+Jul!Q514+Aug!Q514+Sep!Q514+Oct!Q514+Nov!Q514+Dec!Q514+Jan!Q514+Feb!Q514+Mar!Q514)+(Apr!P514+May!P514+Jun!P514+Jul!P514+Aug!P514+Sep!P514+Oct!P514+Nov!P514+Dec!P514+Jan!P514+Feb!P514+Mar!P514),0) -> 0 | M515: =IF(E515="Composition", (Apr!Q514+May!Q514+Jun!Q514+Jul!Q514+Aug!Q514+Sep!Q514+Oct!Q514+Nov!Q514+Dec!Q514+Jan!Q514+Feb!Q514+Mar!Q514)+(Apr!P514+May!P514+Jun!P514+Jul!P514+Aug!P514+Sep!P514+Oct!P514+Nov!P514+Dec!P514+Jan!P514+Feb!P514+Mar!P514),0) -> 0 | N515: =IF(E515="Registered", (Apr!J514+May!J514+Jun!J514+Jul!J514+Aug!J514+Sep!J514+Oct!J514+Nov!J514+Dec!J514+Jan!J514+Feb!J514+Mar!J514),0) -> 0 | O515: =SUM(L515:N515) -> 0 | P515: =IF(E515="Un-registered", (Apr!J514+May!J514+Jun!J514+Jul!J514+Aug!J514+Sep!J514+Oct!J514+Nov!J514+Dec!J514+Jan!J514+Feb!J514+Mar!J514)+(Apr!P514+May!P514+Jun!P514+Jul!P514+Aug!P514+Sep!P514+Oct!P514+Nov!P514+Dec!P514+Jan!P514+Feb!P514+Mar!P514),0) -> 0 | Q515: =J515-K515-O515-P515 -> 0
A516: =+A515+1 -> 500 | B516: =Yearly!B515 -> 0 | C516: =Yearly!C515 -> 0 | D516: =Yearly!D515 -> 0 | E516: =Yearly!E515 -> Composition | F516: =Yearly!F515 -> Composition | G516: =Yearly!G515 -> 0 | H516: =Yearly!H515 -> Exempt | J516: 110 | K516: =Apr!P515+May!P515+Jun!P515+Jul!P515+Aug!P515+Sep!P515+Oct!P515+Nov!P515+Dec!P515+Jan!P515+Feb!P515+Mar!P515 -> 0 | L516: =IF(H516="Exempt", (Apr!Q515+May!Q515+Jun!Q515+Jul!Q515+Aug!Q515+Sep!Q515+Oct!Q515+Nov!Q515+Dec!Q515+Jan!Q515+Feb!Q515+Mar!Q515)+(Apr!P515+May!P515+Jun!P515+Jul!P515+Aug!P515+Sep!P515+Oct!P515+Nov!P515+Dec!P515+Jan!P515+Feb!P515+Mar!P515),0) -> 1320 | M516: =IF(E516="Composition", (Apr!Q515+May!Q515+Jun!Q515+Jul!Q515+Aug!Q515+Sep!Q515+Oct!Q515+Nov!Q515+Dec!Q515+Jan!Q515+Feb!Q515+Mar!Q515)+(Apr!P515+May!P515+Jun!P515+Jul!P515+Aug!P515+Sep!P515+Oct!P515+Nov!P515+Dec!P515+Jan!P515+Feb!P515+Mar!P515),0) -> 1320 | N516: =IF(E516="Registered", (Apr!J515+May!J515+Jun!J515+Jul!J515+Aug!J515+Sep!J515+Oct!J515+Nov!J515+Dec!J515+Jan!J515+Feb!J515+Mar!J515),0) -> 0 | O516: =SUM(L516:N516) -> 2640 | P516: =IF(E516="Un-registered", (Apr!J515+May!J515+Jun!J515+Jul!J515+Aug!J515+Sep!J515+Oct!J515+Nov!J515+Dec!J515+Jan!J515+Feb!J515+Mar!J515)+(Apr!P515+May!P515+Jun!P515+Jul!P515+Aug!P515+Sep!P515+Oct!P515+Nov!P515+Dec!P515+Jan!P515+Feb!P515+Mar!P515),0) -> 0 | Q516: =J516-K516-O516-P516 -> -2530

Sheet Yearly
B2: NAME = | J2: As per Books | T2: As per GSTR 3B | AD2: As per GSTR 1 / 2A
B4: Total | J4: =SUM(J6:J13) -> 0 | K4: =SUM(K6:K13) -> 0 | L4: =SUM(L6:L13) -> 0 | M4: =SUM(M6:M13) -> 0 | N4: =SUM(N6:N13) -> 0 | O4: =SUM(O6:O13) -> 0 | P4: =SUM(P6:P13) -> 0 | Q4: =SUM(Q6:Q13) -> 0 | R4: =SUM(R6:R13) -> 0 | T4: =SUM(T6:T13) -> 0 | U4: =SUM(U6:U13) -> 0 | V4: =SUM(V6:V13) -> 0 | W4: =SUM(W6:W13) -> 0 | X4: =SUM(X6:X13) -> 0 | Y4: =SUM(Y6:Y13) -> 0 | Z4: =SUM(Z6:Z13) -> 0 | AA4: =SUM(AA6:AA13) -> 0 | AB4: =SUM(AB6:AB13) -> 0 | AD4: =SUM(AD6:AD13) -> 0 | AE4: =SUM(AE6:AE13) -> 0 | AF4: =SUM(AF6:AF13) -> 0 | AG4: =SUM(AG6:AG13) -> 0 | AH4: =SUM(AH6:AH13) -> 0 | AI4: =SUM(AI6:AI13) -> 0 | AJ4: =SUM(AJ6:AJ13) -> 0 | AK4: =SUM(AK6:AK13) -> 0 | AL4: =SUM(AL6:AL13) -> 0
B5: Difference | C5: GSTIN = | J5: =SUM(J16:J215)-J4 -> 0 | K5: =SUM(K16:K215)-K4 -> 0 | L5: =SUM(L16:L215)-L4 -> 0 | M5: =SUM(M16:M215)-M4 -> 0 | N5: =SUM(N16:N215)-N4 -> 0 | O5: =SUM(O16:O215)-O4 -> 0 | P5: =SUM(P16:P215)-P4 -> 0 | Q5: =SUM(Q16:Q215)-Q4 -> 0 | R5: =SUM(R16:R215)-R4 -> 0 | T5: =SUM(T16:T215)-T4 -> 0 | U5: =SUM(U16:U215)-U4 -> 0 | V5: =SUM(V16:V215)-V4 -> 0 | W5: =SUM(W16:W215)-W4 -> 0 | X5: =SUM(X16:X215)-X4 -> 0 | Y5: =SUM(Y16:Y215)-Y4 -> 0 | Z5: =SUM(Z16:Z215)-Z4 -> 0 | AA5: =SUM(AA16:AA215)-AA4 -> 0 | AB5: =SUM(AB16:AB215)-AB4 -> 0 | AD5: =SUM(AD16:AD215)-AD4 -> 0 | AE5: =SUM(AE16:AE215)-AE4 -> 0 | AF5: =SUM(AF16:AF215)-AF4 -> 0 | AG5: =SUM(AG16:AG215)-AG4 -> 0 | AH5: =SUM(AH16:AH215)-AH4 -> 0 | AI5: =SUM(AI16:AI215)-AI4 -> 0 | AJ5: =SUM(AJ16:AJ215)-AJ4 -> 0 | AK5: =SUM(AK16:AK215)-AK4 -> 0 | AL5: =SUM(AL16:AL215)-AL4 -> 0
B6: Sales | J6: =SUMIF($B$16:$R$515, B6, $J$16:$J$515) -> 0 | K6: =SUMIF($B$16:$R$515, B6, $K$16:$K$515) -> 0 | L6: =SUMIF($B$16:$R$515, B6, $L$16:$L$515) -> 0 | M6: =SUMIF($B$16:$R$515, B6, $M$16:$M$515) -> 0 | N6: =SUMIF($B$16:$R$515, B6, $N$16:$N$515) -> 0 | O6: =SUMIF($B$16:$R$515, B6, $O$16:$O$515) -> 0 | P6: =SUMIF($B$16:$R$515, B6, $P$16:$P$515) -> 0 | Q6: =SUMIF($B$16:$R$515, B6, $Q$16:$Q$515) -> 0 | R6: =SUMIF($B$16:$R$515, B6, $R$16:$R$515) -> 0 | T6: =SUMIF($B$16:$AB$515, $B$6, T16:T515) -> 0 | U6: =SUMIF($B$16:$AB$515, $B$6, U16:U515) -> 0 | V6: =SUMIF($B$16:$AB$515, $B$6, V16:V515) -> 0 | W6: =SUMIF($B$16:$AB$515, $B$6, W16:W515) -> 0 | X6: =SUMIF($B$16:$AB$515, $B$6, X16:X515) -> 0 | Y6: =SUMIF($B$16:$AB$515, $B$6, Y16:Y515) -> 0 | Z6: =SUMIF($B$16:$AB$515, $B$6, Z16:Z515) -> 0 | AA6: =SUMIF($B$16:$AB$515, $B$6, AA16:AA515) -> 0 | AB6: =SUMIF($B$16:$AB$515, $B$6, AB16:AB515) -> 0 | AD6: =SUMIF($B$16:$AL$515, $B$6, AD16:AD515) -> 0 | AE6: =SUMIF($B$16:$AL$515, $B$6, AE16:AE515) -> 0 | AF6: =SUMIF($B$16:$AL$515, $B$6, AF16:AF515) -> 0 | AG6: =SUMIF($B$16:$AL$515, $B$6, AG16:AG515) -> 0 | AH6: =SUMIF($B$16:$AL$515, $B$6, AH16:AH515) -> 0 | AI6: =SUMIF($B$16:$AL$515, $B$6, AI16:AI515) -> 0 | AJ6: =SUMIF($B$16:$AL$515, $B$6, AJ16:AJ515) -> 0 | AK6: =SUMIF($B$16:$AL$515, $B$6, AK16:AK515) -> 0 | AL6: =SUMIF($B$16:$AL$515, $B$6, AL16:AL515) -> 0
B7: Direct Incomes | J7: =SUMIF($B$16:$R$515, B7, $J$16:$J$515) -> 0 | K7: =SUMIF($B$16:$R$515, B7, $K$16:$K$515) -> 0 | L7: =SUMIF($B$16:$R$515, B7, $L$16:$L$515) -> 0 | M7: =SUMIF($B$16:$R$515, B7, $M$16:$M$515) -> 0 | N7: =SUMIF($B$16:$R$515, B7, $N$16:$N$515) -> 0 | O7: =SUMIF($B$16:$R$515, B7, $O$16:$O$515) -> 0 | P7: =SUMIF($B$16:$R$515, B7, $P$16:$P$515) -> 0 | Q7: =SUMIF($B$16:$R$515, B7, $Q$16:$Q$515) -> 0 | R7: =SUMIF($B$16:$R$515, B7, $R$16:$R$515) -> 0 | T7: =SUMIF($B$16:$AB$515, $B$7, T16:T515) -> 0 | U7: =SUMIF($B$16:$AB$515, $B$7, U16:U515) -> 0 | V7: =SUMIF($B$16:$AB$515, $B$7, V16:V515) -> 0 | W7: =SUMIF($B$16:$AB$515, $B$7, W16:W515) -> 0 | X7: =SUMIF($B$16:$AB$515, $B$7, X16:X515) -> 0 | Y7: =SUMIF($B$16:$AB$515, $B$7, Y16:Y515) -> 0 | Z7: =SUMIF($B$16:$AB$515, $B$7, Z16:Z515) -> 0 | AA7: =SUMIF($B$16:$AB$515, $B$7, AA16:AA515) -> 0 | AB7: =SUMIF($B$16:$AB$515, $B$7, AB16:AB515) -> 0 | AD7: =SUMIF($B$16:$AL$515, $B$7, AD16:AD515) -> 0 | AE7: =SUMIF($B$16:$AL$515, $B$7, AE16:AE515) -> 0 | AF7: =SUMIF($B$16:$AL$515, $B$7, AF16:AF515) -> 0 | AG7: =SUMIF($B$16:$AL$515, $B$7, AG16:AG515) -> 0 | AH7: =SUMIF($B$16:$AL$515, $B$7, AH16:AH515) -> 0 | AI7: =SUMIF($B$16:$AL$515, $B$7, AI16:AI515) -> 0 | AJ7: =SUMIF($B$16:$AL$515, $B$7, AJ16:AJ515) -> 0 | AK7: =SUMIF($B$16:$AL$515, $B$7, AK16:AK515) -> 0 | AL7: =SUMIF($B$16:$AL$515, $B$7, AL16:AL515) -> 0
B8: Indirect Incomes | C8: YEAR = | D8: 2017-18 | J8: =SUMIF($B$16:$R$515, B8, $J$16:$J$515) -> 0 | K8: =SUMIF($B$16:$R$515, B8, $K$16:$K$515) -> 0 | L8: =SUMIF($B$16:$R$515, B8, $L$16:$L$515) -> 0 | M8: =SUMIF($B$16:$R$515, B8, $M$16:$M$515) -> 0 | N8: =SUMIF($B$16:$R$515, B8, $N$16:$N$515) -> 0 | O8: =SUMIF($B$16:$R$515, B8, $O$16:$O$515) -> 0 | P8: =SUMIF($B$16:$R$515, B8, $P$16:$P$515) -> 0 | Q8: =SUMIF($B$16:$R$515, B8, $Q$16:$Q$515) -> 0 | R8: =SUMIF($B$16:$R$515, B8, $R$16:$R$515) -> 0 | T8: =SUMIF($B$16:$AB$515, $B$8, T16:T515) -> 0 | U8: =SUMIF($B$16:$AB$515, $B$8, U16:U515) -> 0 | V8: =SUMIF($B$16:$AB$515, $B$8, V16:V515) -> 0 | W8: =SUMIF($B$16:$AB$515, $B$8, W16:W515) -> 0 | X8: =SUMIF($B$16:$AB$515, $B$8, X16:X515) -> 0 | Y8: =SUMIF($B$16:$AB$515, $B$8, Y16:Y515) -> 0 | Z8: =SUMIF($B$16:$AB$515, $B$8, Z16:Z515) -> 0 | AA8: =SUMIF($B$16:$AB$515, $B$8, AA16:AA515) -> 0 | AB8: =SUMIF($B$16:$AB$515, $B$8, AB16:AB515) -> 0 | AD8: =SUMIF($B$16:$AL$515, $B$8, AD16:AD515) -> 0 | AE8: =SUMIF($B$16:$AL$515, $B$8, AE16:AE515) -> 0 | AF8: =SUMIF($B$16:$AL$515, $B$8, AF16:AF515) -> 0 | AG8: =SUMIF($B$16:$AL$515, $B$8, AG16:AG515) -> 0 | AH8: =SUMIF($B$16:$AL$515, $B$8, AH16:AH515) -> 0 | AI8: =SUMIF($B$16:$AL$515, $B$8, AI16:AI515) -> 0 | AJ8: =SUMIF($B$16:$AL$515, $B$8, AJ16:AJ515) -> 0 | AK8: =SUMIF($B$16:$AL$515, $B$8, AK16:AK515) -> 0 | AL8: =SUMIF($B$16:$AL$515, $B$8, AL16:AL515) -> 0
B9: Purchases | J9: =SUMIF($B$16:$R$515, B9, $J$16:$J$515) -> 0 | K9: =SUMIF($B$16:$R$515, B9, $K$16:$K$515) -> 0 | L9: =SUMIF($B$16:$R$515, B9, $L$16:$L$515) -> 0 | M9: =SUMIF($B$16:$R$515, B9, $M$16:$M$515) -> 0 | N9: =SUMIF($B$16:$R$515, B9, $N$16:$N$515) -> 0 | O9: =SUMIF($B$16:$R$515, B9, $O$16:$O$515) -> 0 | P9: =SUMIF($B$16:$R$515, B9, $P$16:$P$515) -> 0 | Q9: =SUMIF($B$16:$R$515, B9, $Q$16:$Q$515) -> 0 | R9: =SUMIF($B$16:$R$515, B9, $R$16:$R$515) -> 0 | T9: =SUMIF($B$16:$AB$515, $B$9, T16:T515) -> 0 | U9: =SUMIF($B$16:$AB$515, $B$9, U16:U515) -> 0 | V9: =SUMIF($B$16:$AB$515, $B$9, V16:V515) -> 0 | W9: =SUMIF($B$16:$AB$515, $B$9, W16:W515) -> 0 | X9: =SUMIF($B$16:$AB$515, $B$9, X16:X515) -> 0 | Y9: =SUMIF($B$16:$AB$515, $B$9, Y16:Y515) -> 0 | Z9: =SUMIF($B$16:$AB$515, $B$9, Z16:Z515) -> 0 | AA9: =SUMIF($B$16:$AB$515, $B$9, AA16:AA515) -> 0 | AB9: =SUMIF($B$16:$AB$515, $B$9, AB16:AB515) -> 0 | AD9: =SUMIF($B$16:$AL$515, $B$9, AD16:AD515) -> 0 | AE9: =SUMIF($B$16:$AL$515, $B$9, AE16:AE515) -> 0 | AF9: =SUMIF($B$16:$AL$515, $B$9, AF16:AF515) -> 0 | AG9: =SUMIF($B$16:$AL$515, $B$9, AG16:AG515) -> 0 | AH9: =SUMIF($B$16:$AL$515, $B$9, AH16:AH515) -> 0 | AI9: =SUMIF($B$16:$AL$515, $B$9, AI16:AI515) -> 0 | AJ9: =SUMIF($B$16:$AL$515, $B$9, AJ16:AJ515) -> 0 | AK9: =SUMIF($B$16:$AL$515, $B$9, AK16:AK515) -> 0 | AL9: =SUMIF($B$16:$AL$515, $B$9, AL16:AL515) -> 0
B10: Direct Expenses | J10: =SUMIF($B$16:$R$515, B10, $J$16:$J$515) -> 0 | K10: =SUMIF($B$16:$R$515, B10, $K$16:$K$515) -> 0 | L10: =SUMIF($B$16:$R$515, B10, $L$16:$L$515) -> 0 | M10: =SUMIF($B$16:$R$515, B10, $M$16:$M$515) -> 0 | N10: =SUMIF($B$16:$R$515, B10, $N$16:$N$515) -> 0 | O10: =SUMIF($B$16:$R$515, B10, $O$16:$O$515) -> 0 | P10: =SUMIF($B$16:$R$515, B10, $P$16:$P$515) -> 0 | Q10: =SUMIF($B$16:$R$515, B10, $Q$16:$Q$515) -> 0 | R10: =SUMIF($B$16:$R$515, B10, $R$16:$R$515) -> 0 | T10: =SUMIF($B$16:$AB$515, $B$10, T16:T515) -> 0 | U10: =SUMIF($B$16:$AB$515, $B$10, U16:U515) -> 0 | V10: =SUMIF($B$16:$AB$515, $B$10, V16:V515) -> 0 | W10: =SUMIF($B$16:$AB$515, $B$10, W16:W515) -> 0 | X10: =SUMIF($B$16:$AB$515, $B$10, X16:X515) -> 0 | Y10: =SUMIF($B$16:$AB$515, $B$10, Y16:Y515) -> 0 | Z10: =SUMIF($B$16:$AB$515, $B$10, Z16:Z515) -> 0 | AA10: =SUMIF($B$16:$AB$515, $B$10, AA16:AA515) -> 0 | AB10: =SUMIF($B$16:$AB$515, $B$10, AB16:AB515) -> 0 | AD10: =SUMIF($B$16:$AL$515, $B$10, AD16:AD515) -> 0 | AE10: =SUMIF($B$16:$AL$515, $B$10, AE16:AE515) -> 0 | AF10: =SUMIF($B$16:$AL$515, $B$10, AF16:AF515) -> 0 | AG10: =SUMIF($B$16:$AL$515, $B$10, AG16:AG515) -> 0 | AH10: =SUMIF($B$16:$AL$515, $B$10, AH16:AH515) -> 0 | AI10: =SUMIF($B$16:$AL$515, $B$10, AI16:AI515) -> 0 | AJ10: =SUMIF($B$16:$AL$515, $B$10, AJ16:AJ515) -> 0 | AK10: =SUMIF($B$16:$AL$515, $B$10, AK16:AK515) -> 0 | AL10: =SUMIF($B$16:$AL$515, $B$10, AL16:AL515) -> 0
B11: Indirect Expenses | C11: MONTH = | D11: APRIL TO MARCH | J11: =SUMIF($B$16:$R$515, B11, $J$16:$J$515) -> 0 | K11: =SUMIF($B$16:$R$515, B11, $K$16:$K$515) -> 0 | L11: =SUMIF($B$16:$R$515, B11, $L$16:$L$515) -> 0 | M11: =SUMIF($B$16:$R$515, B11, $M$16:$M$515) -> 0 | N11: =SUMIF($B$16:$R$515, B11, $N$16:$N$515) -> 0 | O11: =SUMIF($B$16:$R$515, B11, $O$16:$O$515) -> 0 | P11: =SUMIF($B$16:$R$515, B11, $P$16:$P$515) -> 0 | Q11: =SUMIF($B$16:$R$515, B11, $Q$16:$Q$515) -> 0 | R11: =SUMIF($B$16:$R$515, B11, $R$16:$R$515) -> 0 | T11: =SUMIF($B$16:$AB$515, $B$11, T16:T515) -> 0 | U11: =SUMIF($B$16:$AB$515, $B$11, U16:U515) -> 0 | V11: =SUMIF($B$16:$AB$515, $B$11, V16:V515) -> 0 | W11: =SUMIF($B$16:$AB$515, $B$11, W16:W515) -> 0 | X11: =SUMIF($B$16:$AB$515, $B$11, X16:X515) -> 0 | Y11: =SUMIF($B$16:$AB$515, $B$11, Y16:Y515) -> 0 | Z11: =SUMIF($B$16:$AB$515, $B$11, Z16:Z515) -> 0 | AA11: =SUMIF($B$16:$AB$515, $B$11, AA16:AA515) -> 0 | AB11: =SUMIF($B$16:$AB$515, $B$11, AB16:AB515) -> 0 | AD11: =SUMIF($B$16:$AL$515, $B$11, AD16:AD515) -> 0 | AE11: =SUMIF($B$16:$AL$515, $B$11, AE16:AE515) -> 0 | AF11: =SUMIF($B$16:$AL$515, $B$11, AF16:AF515) -> 0 | AG11: =SUMIF($B$16:$AL$515, $B$11, AG16:AG515) -> 0 | AH11: =SUMIF($B$16:$AL$515, $B$11, AH16:AH515) -> 0 | AI11: =SUMIF($B$16:$AL$515, $B$11, AI16:AI515) -> 0 | AJ11: =SUMIF($B$16:$AL$515, $B$11, AJ16:AJ515) -> 0 | AK11: =SUMIF($B$16:$AL$515, $B$11, AK16:AK515) -> 0 | AL11: =SUMIF($B$16:$AL$515, $B$11, AL16:AL515) -> 0
B12: Capital Assets | J12: =SUMIF($B$16:$R$515, B12, $J$16:$J$515) -> 0 | K12: =SUMIF($B$16:$R$515, B12, $K$16:$K$515) -> 0 | L12: =SUMIF($B$16:$R$515, B12, $L$16:$L$515) -> 0 | M12: =SUMIF($B$16:$R$515, B12, $M$16:$M$515) -> 0 | N12: =SUMIF($B$16:$R$515, B12, $N$16:$N$515) -> 0 | O12: =SUMIF($B$16:$R$515, B12, $O$16:$O$515) -> 0 | P12: =SUMIF($B$16:$R$515, B12, $P$16:$P$515) -> 0 | Q12: =SUMIF($B$16:$R$515, B12, $Q$16:$Q$515) -> 0 | R12: =SUMIF($B$16:$R$515, B12, $R$16:$R$515) -> 0 | T12: =SUMIF($B$16:$AB$515, $B$12, T16:T515) -> 0 | U12: =SUMIF($B$16:$AB$515, $B$12, U16:U515) -> 0 | V12: =SUMIF($B$16:$AB$515, $B$12, V16:V515) -> 0 | W12: =SUMIF($B$16:$AB$515, $B$12, W16:W515) -> 0 | X12: =SUMIF($B$16:$AB$515, $B$12, X16:X515) -> 0 | Y12: =SUMIF($B$16:$AB$515, $B$12, Y16:Y515) -> 0 | Z12: =SUMIF($B$16:$AB$515, $B$12, Z16:Z515) -> 0 | AA12: =SUMIF($B$16:$AB$515, $B$12, AA16:AA515) -> 0 | AB12: =SUMIF($B$16:$AB$515, $B$12, AB16:AB515) -> 0 | AD12: =SUMIF($B$16:$AL$515, $B$12, AD16:AD515) -> 0 | AE12: =SUMIF($B$16:$AL$515, $B$12, AE16:AE515) -> 0 | AF12: =SUMIF($B$16:$AL$515, $B$12, AF16:AF515) -> 0 | AG12: =SUMIF($B$16:$AL$515, $B$12, AG16:AG515) -> 0 | AH12: =SUMIF($B$16:$AL$515, $B$12, AH16:AH515) -> 0 | AI12: =SUMIF($B$16:$AL$515, $B$12, AI16:AI515) -> 0 | AJ12: =SUMIF($B$16:$AL$515, $B$12, AJ16:AJ515) -> 0 | AK12: =SUMIF($B$16:$AL$515, $B$12, AK16:AK515) -> 0 | AL12: =SUMIF($B$16:$AL$515, $B$12, AL16:AL515) -> 0
B13: Others | J13: =SUMIF($B$16:$R$515, B13, $J$16:$J$515) -> 0 | K13: =SUMIF($B$16:$R$515, B13, $K$16:$K$515) -> 0 | L13: =SUMIF($B$16:$R$515, B13, $L$16:$L$515) -> 0 | M13: =SUMIF($B$16:$R$515, B13, $M$16:$M$515) -> 0 | N13: =SUMIF($B$16:$R$515, B13, $N$16:$N$515) -> 0 | O13: =SUMIF($B$16:$R$515, B13, $O$16:$O$515) -> 0 | P13: =SUMIF($B$16:$R$515, B13, $P$16:$P$515) -> 0 | Q13: =SUMIF($B$16:$R$515, B13, $Q$16:$Q$515) -> 0 | R13: =SUMIF($B$16:$R$515, B13, $R$16:$R$515) -> 0 | T13: =SUMIF($B$16:$AB$515, $B$13, T16:T515) -> 0 | U13: =SUMIF($B$16:$AB$515, $B$13, U16:U515) -> 0 | V13: =SUMIF($B$16:$AB$515, $B$13, V16:V515) -> 0 | W13: =SUMIF($B$16:$AB$515, $B$13, W16:W515) -> 0 | X13: =SUMIF($B$16:$AB$515, $B$13, X16:X515) -> 0 | Y13: =SUMIF($B$16:$AB$515, $B$13, Y16:Y515) -> 0 | Z13: =SUMIF($B$16:$AB$515, $B$13, Z16:Z515) -> 0 | AA13: =SUMIF($B$16:$AB$515, $B$13, AA16:AA515) -> 0 | AB13: =SUMIF($B$16:$AB$515, $B$13, AB16:AB515) -> 0 | AD13: =SUMIF($B$16:$AL$515, $B$13, AD16:AD515) -> 0 | AE13: =SUMIF($B$16:$AL$515, $B$13, AE16:AE515) -> 0 | AF13: =SUMIF($B$16:$AL$515, $B$13, AF16:AF515) -> 0 | AG13: =SUMIF($B$16:$AL$515, $B$13, AG16:AG515) -> 0 | AH13: =SUMIF($B$16:$AL$515, $B$13, AH16:AH515) -> 0 | AI13: =SUMIF($B$16:$AL$515, $B$13, AI16:AI515) -> 0 | AJ13: =SUMIF($B$16:$AL$515, $B$13, AJ16:AJ515) -> 0 | AK13: =SUMIF($B$16:$AL$515, $B$13, AK16:AK515) -> 0 | AL13: =SUMIF($B$16:$AL$515, $B$13, AL16:AL515) -> 0
A15: Sr. No. | B15: Nature of Transaction | C15: Head as per Financial Statements | D15: Type of Item | E15: Type of Dealer | F15: Document | G15: HSN | H15: Tax Rate | J15: Taxable Value | K15: CGST | L15: SGST | M15: IGST | N15: Cess | O15: Total GST | P15: Non-GST | Q15: Invoice Value | R15: Validation | T15: Taxable Value | U15: CGST | V15: SGST | W15: IGST | X15: Cess | Y15: Total GST | Z15: Non-GST | AA15: Invoice Value | AB15: Validation | AD15: Taxable Value | AE15: CGST | AF15: SGST | AG15: IGST | AH15: Cess | AI15: Total GST | AJ15: Non-GST | AK15: Invoice Value | AL15: Validation
A16: 1 | J16: =Apr!J16+May!J16+Jun!J16+Jul!J16+Aug!J16+Sep!J16+Oct!J16+Nov!J16+Dec!J16+Jan!J16+Feb!J16+Mar!J16 -> 0 | K16: =Apr!K16+May!K16+Jun!K16+Jul!K16+Aug!K16+Sep!K16+Oct!K16+Nov!K16+Dec!K16+Jan!K16+Feb!K16+Mar!K16 -> 0 | L16: =Apr!L16+May!L16+Jun!L16+Jul!L16+Aug!L16+Sep!L16+Oct!L16+Nov!L16+Dec!L16+Jan!L16+Feb!L16+Mar!L16 -> 0 | M16: =Apr!M16+May!M16+Jun!M16+Jul!M16+Aug!M16+Sep!M16+Oct!M16+Nov!M16+Dec!M16+Jan!M16+Feb!M16+Mar!M16 -> 0 | N16: =Apr!N16+May!N16+Jun!N16+Jul!N16+Aug!N16+Sep!N16+Oct!N16+Nov!N16+Dec!N16+Jan!N16+Feb!N16+Mar!N16 -> 0 | O16: =SUM(K16:N16) -> 0 | P16: =Apr!P16+May!P16+Jun!P16+Jul!P16+Aug!P16+Sep!P16+Oct!P16+Nov!P16+Dec!P16+Jan!P16+Feb!P16+Mar!P16 -> 0 | Q16: =J16+O16+P16 -> 0 | R16: =IF(H16="Exempt",0,ROUND((J16*H16/100)-SUM(K16:M16),2)) -> 0 | T16: =Apr!T16+May!T16+Jun!T16+Jul!T16+Aug!T16+Sep!T16+Oct!T16+Nov!T16+Dec!T16+Jan!T16+Feb!T16+Mar!T16 -> 0 | U16: =Apr!U16+May!U16+Jun!U16+Jul!U16+Aug!U16+Sep!U16+Oct!U16+Nov!U16+Dec!U16+Jan!U16+Feb!U16+Mar!U16 -> 0 | V16: =Apr!V16+May!V16+Jun!V16+Jul!V16+Aug!V16+Sep!V16+Oct!V16+Nov!V16+Dec!V16+Jan!V16+Feb!V16+Mar!V16 -> 0 | W16: =Apr!W16+May!W16+Jun!W16+Jul!W16+Aug!W16+Sep!W16+Oct!W16+Nov!W16+Dec!W16+Jan!W16+Feb!W16+Mar!W16 -> 0 | X16: =Apr!X16+May!X16+Jun!X16+Jul!X16+Aug!X16+Sep!X16+Oct!X16+Nov!X16+Dec!X16+Jan!X16+Feb!X16+Mar!X16 -> 0 | Y16: =SUM(U16:X16) -> 0 | Z16: =Apr!Z16+May!Z16+Jun!Z16+Jul!Z16+Aug!Z16+Sep!Z16+Oct!Z16+Nov!Z16+Dec!Z16+Jan!Z16+Feb!Z16+Mar!Z16 -> 0 | AA16: =T16+Y16+Z16 -> 0 | AB16: =IF(H16="Exempt",0,ROUND((T16*H16/100)-SUM(U16:W16),2)) -> 0 | AD16: =Apr!AD16+May!AD16+Jun!AD16+Jul!AD16+Aug!AD16+Sep!AD16+Oct!AD16+Nov!AD16+Dec!AD16+Jan!AD16+Feb!AD16+Mar!AD16 -> 0 | AE16: =Apr!AE16+May!AE16+Jun!AE16+Jul!AE16+Aug!AE16+Sep!AE16+Oct!AE16+Nov!AE16+Dec!AE16+Jan!AE16+Feb!AE16+Mar!AE16 -> 0 | AF16: =Apr!AF16+May!AF16+Jun!AF16+Jul!AF16+Aug!AF16+Sep!AF16+Oct!AF16+Nov!AF16+Dec!AF16+Jan!AF16+Feb!AF16+Mar!AF16 -> 0 | AG16: =Apr!AG16+May!AG16+Jun!AG16+Jul!AG16+Aug!AG16+Sep!AG16+Oct!AG16+Nov!AG16+Dec!AG16+Jan!AG16+Feb!AG16+Mar!AG16 -> 0 | AI16: =SUM(AE16:AH16) -> 0 | AJ16: =Apr!AJ16+May!AJ16+Jun!AJ16+Jul!AJ16+Aug!AJ16+Sep!AJ16+Oct!AJ16+Nov!AJ16+Dec!AJ16+Jan!AJ16+Feb!AJ16+Mar!AJ16 -> 0 | AK16: =AD16+AI16+AJ16 -> 0 | AL16: =IF(H16="Exempt",0,ROUND((AD16*H16/100)-SUM(AE16:AG16),2)) -> 0 | AO16: Goods | AP16: Registered | AQ16: Tax Invoice | AR16: 28
A17: =+A16+1 -> 2 | J17: =Apr!J17+May!J17+Jun!J17+Jul!J17+Aug!J17+Sep!J17+Oct!J17+Nov!J17+Dec!J17+Jan!J17+Feb!J17+Mar!J17 -> 0 | K17: =Apr!K17+May!K17+Jun!K17+Jul!K17+Aug!K17+Sep!K17+Oct!K17+Nov!K17+Dec!K17+Jan!K17+Feb!K17+Mar!K17 -> 0 | L17: =Apr!L17+May!L17+Jun!L17+Jul!L17+Aug!L17+Sep!L17+Oct!L17+Nov!L17+Dec!L17+Jan!L17+Feb!L17+Mar!L17 -> 0 | M17: =Apr!M17+May!M17+Jun!M17+Jul!M17+Aug!M17+Sep!M17+Oct!M17+Nov!M17+Dec!M17+Jan!M17+Feb!M17+Mar!M17 -> 0 | N17: =Apr!N17+May!N17+Jun!N17+Jul!N17+Aug!N17+Sep!N17+Oct!N17+Nov!N17+Dec!N17+Jan!N17+Feb!N17+Mar!N17 -> 0 | O17: =SUM(K17:N17) -> 0 | P17: =Apr!P17+May!P17+Jun!P17+Jul!P17+Aug!P17+Sep!P17+Oct!P17+Nov!P17+Dec!P17+Jan!P17+Feb!P17+Mar!P17 -> 0 | Q17: =J17+O17+P17 -> 0 | R17: =IF(H17="Exempt",0,ROUND((J17*H17/100)-SUM(K17:M17),2)) -> 0 | T17: =Apr!T17+May!T17+Jun!T17+Jul!T17+Aug!T17+Sep!T17+Oct!T17+Nov!T17+Dec!T17+Jan!T17+Feb!T17+Mar!T17 -> 0 | U17: =Apr!U17+May!U17+Jun!U17+Jul!U17+Aug!U17+Sep!U17+Oct!U17+Nov!U17+Dec!U17+Jan!U17+Feb!U17+Mar!U17 -> 0 | V17: =Apr!V17+May!V17+Jun!V17+Jul!V17+Aug!V17+Sep!V17+Oct!V17+Nov!V17+Dec!V17+Jan!V17+Feb!V17+Mar!V17 -> 0 | W17: =Apr!W17+May!W17+Jun!W17+Jul!W17+Aug!W17+Sep!W17+Oct!W17+Nov!W17+Dec!W17+Jan!W17+Feb!W17+Mar!W17 -> 0 | X17: =Apr!X17+May!X17+Jun!X17+Jul!X17+Aug!X17+Sep!X17+Oct!X17+Nov!X17+Dec!X17+Jan!X17+Feb!X17+Mar!X17 -> 0 | Y17: =SUM(U17:X17) -> 0 | Z17: =Apr!Z17+May!Z17+Jun!Z17+Jul!Z17+Aug!Z17+Sep!Z17+Oct!Z17+Nov!Z17+Dec!Z17+Jan!Z17+Feb!Z17+Mar!Z17 -> 0 | AA17: =T17+Y17+Z17 -> 0 | AB17: =IF(H17="Exempt",0,ROUND((T17*H17/100)-SUM(U17:W17),2)) -> 0 | AD17: =Apr!AD17+May!AD17+Jun!AD17+Jul!AD17+Aug!AD17+Sep!AD17+Oct!AD17+Nov!AD17+Dec!AD17+Jan!AD17+Feb!AD17+Mar!AD17 -> 0 | AE17: =Apr!AE17+May!AE17+Jun!AE17+Jul!AE17+Aug!AE17+Sep!AE17+Oct!AE17+Nov!AE17+Dec!AE17+Jan!AE17+Feb!AE17+Mar!AE17 -> 0 | AF17: =Apr!AF17+May!AF17+Jun!AF17+Jul!AF17+Aug!AF17+Sep!AF17+Oct!AF17+Nov!AF17+Dec!AF17+Jan!AF17+Feb!AF17+Mar!AF17 -> 0 | AG17: =Apr!AG17+May!AG17+Jun!AG17+Jul!AG17+Aug!AG17+Sep!AG17+Oct!AG17+Nov!AG17+Dec!AG17+Jan!AG17+Feb!AG17+Mar!AG17 -> 0 | AI17: =SUM(AE17:AH17) -> 0 | AJ17: =Apr!AJ17+May!AJ17+Jun!AJ17+Jul!AJ17+Aug!AJ17+Sep!AJ17+Oct!AJ17+Nov!AJ17+Dec!AJ17+Jan!AJ17+Feb!AJ17+Mar!AJ17 -> 0 | AK17: =AD17+AI17+AJ17 -> 0 | AL17: =IF(H17="Exempt",0,ROUND((AD17*H17/100)-SUM(AE17:AG17),2)) -> 0 | AO17: Services | AP17: Unregistered | AQ17: Debit Note | AR17: 18
A18: =+A17+1 -> 3 | J18: =Apr!J18+May!J18+Jun!J18+Jul!J18+Aug!J18+Sep!J18+Oct!J18+Nov!J18+Dec!J18+Jan!J18+Feb!J18+Mar!J18 -> 0 | K18: =Apr!K18+May!K18+Jun!K18+Jul!K18+Aug!K18+Sep!K18+Oct!K18+Nov!K18+Dec!K18+Jan!K18+Feb!K18+Mar!K18 -> 0 | L18: =Apr!L18+May!L18+Jun!L18+Jul!L18+Aug!L18+Sep!L18+Oct!L18+Nov!L18+Dec!L18+Jan!L18+Feb!L18+Mar!L18 -> 0 | M18: =Apr!M18+May!M18+Jun!M18+Jul!M18+Aug!M18+Sep!M18+Oct!M18+Nov!M18+Dec!M18+Jan!M18+Feb!M18+Mar!M18 -> 0 | N18: =Apr!N18+May!N18+Jun!N18+Jul!N18+Aug!N18+Sep!N18+Oct!N18+Nov!N18+Dec!N18+Jan!N18+Feb!N18+Mar!N18 -> 0 | O18: =SUM(K18:N18) -> 0 | P18: =Apr!P18+May!P18+Jun!P18+Jul!P18+Aug!P18+Sep!P18+Oct!P18+Nov!P18+Dec!P18+Jan!P18+Feb!P18+Mar!P18 -> 0 | Q18: =J18+O18+P18 -> 0 | R18: =IF(H18="Exempt",0,ROUND((J18*H18/100)-SUM(K18:M18),2)) -> 0 | T18: =Apr!T18+May!T18+Jun!T18+Jul!T18+Aug!T18+Sep!T18+Oct!T18+Nov!T18+Dec!T18+Jan!T18+Feb!T18+Mar!T18 -> 0 | U18: =Apr!U18+May!U18+Jun!U18+Jul!U18+Aug!U18+Sep!U18+Oct!U18+Nov!U18+Dec!U18+Jan!U18+Feb!U18+Mar!U18 -> 0 | V18: =Apr!V18+May!V18+Jun!V18+Jul!V18+Aug!V18+Sep!V18+Oct!V18+Nov!V18+Dec!V18+Jan!V18+Feb!V18+Mar!V18 -> 0 | W18: =Apr!W18+May!W18+Jun!W18+Jul!W18+Aug!W18+Sep!W18+Oct!W18+Nov!W18+Dec!W18+Jan!W18+Feb!W18+Mar!W18 -> 0 | X18: =Apr!X18+May!X18+Jun!X18+Jul!X18+Aug!X18+Sep!X18+Oct!X18+Nov!X18+Dec!X18+Jan!X18+Feb!X18+Mar!X18 -> 0 | Y18: =SUM(U18:X18) -> 0 | Z18: =Apr!Z18+May!Z18+Jun!Z18+Jul!Z18+Aug!Z18+Sep!Z18+Oct!Z18+Nov!Z18+Dec!Z18+Jan!Z18+Feb!Z18+Mar!Z18 -> 0 | AA18: =T18+Y18+Z18 -> 0 | AB18: =IF(H18="Exempt",0,ROUND((T18*H18/100)-SUM(U18:W18),2)) -> 0 | AD18: =Apr!AD18+May!AD18+Jun!AD18+Jul!AD18+Aug!AD18+Sep!AD18+Oct!AD18+Nov!AD18+Dec!AD18+Jan!AD18+Feb!AD18+Mar!AD18 -> 0 | AE18: =Apr!AE18+May!AE18+Jun!AE18+Jul!AE18+Aug!AE18+Sep!AE18+Oct!AE18+Nov!AE18+Dec!AE18+Jan!AE18+Feb!AE18+Mar!AE18 -> 0 | AF18: =Apr!AF18+May!AF18+Jun!AF18+Jul!AF18+Aug!AF18+Sep!AF18+Oct!AF18+Nov!AF18+Dec!AF18+Jan!AF18+Feb!AF18+Mar!AF18 -> 0 | AG18: =Apr!AG18+May!AG18+Jun!AG18+Jul!AG18+Aug!AG18+Sep!AG18+Oct!AG18+Nov!AG18+Dec!AG18+Jan!AG18+Feb!AG18+Mar!AG18 -> 0 | AI18: =SUM(AE18:AH18) -> 0 | AJ18: =Apr!AJ18+May!AJ18+Jun!AJ18+Jul!AJ18+Aug!AJ18+Sep!AJ18+Oct!AJ18+Nov!AJ18+Dec!AJ18+Jan!AJ18+Feb!AJ18+Mar!AJ18 -> 0 | AK18: =AD18+AI18+AJ18 -> 0 | AL18: =IF(H18="Exempt",0,ROUND((AD18*H18/100)-SUM(AE18:AG18),2)) -> 0 | AO18: Capital Assets | AP18: Composition | AQ18: Credit Note | AR18: 12
A19: =+A18+1 -> 4 | J19: =Apr!J19+May!J19+Jun!J19+Jul!J19+Aug!J19+Sep!J19+Oct!J19+Nov!J19+Dec!J19+Jan!J19+Feb!J19+Mar!J19 -> 0 | K19: =Apr!K19+May!K19+Jun!K19+Jul!K19+Aug!K19+Sep!K19+Oct!K19+Nov!K19+Dec!K19+Jan!K19+Feb!K19+Mar!K19 -> 0 | L19: =Apr!L19+May!L19+Jun!L19+Jul!L19+Aug!L19+Sep!L19+Oct!L19+Nov!L19+Dec!L19+Jan!L19+Feb!L19+Mar!L19 -> 0 | M19: =Apr!M19+May!M19+Jun!M19+Jul!M19+Aug!M19+Sep!M19+Oct!M19+Nov!M19+Dec!M19+Jan!M19+Feb!M19+Mar!M19 -> 0 | N19: =Apr!N19+May!N19+Jun!N19+Jul!N19+Aug!N19+Sep!N19+Oct!N19+Nov!N19+Dec!N19+Jan!N19+Feb!N19+Mar!N19 -> 0 | O19: =SUM(K19:N19) -> 0 | P19: =Apr!P19+May!P19+Jun!P19+Jul!P19+Aug!P19+Sep!P19+Oct!P19+Nov!P19+Dec!P19+Jan!P19+Feb!P19+Mar!P19 -> 0 | Q19: =J19+O19+P19 -> 0 | R19: =IF(H19="Exempt",0,ROUND((J19*H19/100)-SUM(K19:M19),2)) -> 0 | T19: =Apr!T19+May!T19+Jun!T19+Jul!T19+Aug!T19+Sep!T19+Oct!T19+Nov!T19+Dec!T19+Jan!T19+Feb!T19+Mar!T19 -> 0 | U19: =Apr!U19+May!U19+Jun!U19+Jul!U19+Aug!U19+Sep!U19+Oct!U19+Nov!U19+Dec!U19+Jan!U19+Feb!U19+Mar!U19 -> 0 | V19: =Apr!V19+May!V19+Jun!V19+Jul!V19+Aug!V19+Sep!V19+Oct!V19+Nov!V19+Dec!V19+Jan!V19+Feb!V19+Mar!V19 -> 0 | W19: =Apr!W19+May!W19+Jun!W19+Jul!W19+Aug!W19+Sep!W19+Oct!W19+Nov!W19+Dec!W19+Jan!W19+Feb!W19+Mar!W19 -> 0 | X19: =Apr!X19+May!X19+Jun!X19+Jul!X19+Aug!X19+Sep!X19+Oct!X19+Nov!X19+Dec!X19+Jan!X19+Feb!X19+Mar!X19 -> 0 | Y19: =SUM(U19:X19) -> 0 | Z19: =Apr!Z19+May!Z19+Jun!Z19+Jul!Z19+Aug!Z19+Sep!Z19+Oct!Z19+Nov!Z19+Dec!Z19+Jan!Z19+Feb!Z19+Mar!Z19 -> 0 | AA19: =T19+Y19+Z19 -> 0 | AB19: =IF(H19="Exempt",0,ROUND((T19*H19/100)-SUM(U19:W19),2)) -> 0 | AD19: =Apr!AD19+May!AD19+Jun!AD19+Jul!AD19+Aug!AD19+Sep!AD19+Oct!AD19+Nov!AD19+Dec!AD19+Jan!AD19+Feb!AD19+Mar!AD19 -> 0 | AE19: =Apr!AE19+May!AE19+Jun!AE19+Jul!AE19+Aug!AE19+Sep!AE19+Oct!AE19+Nov!AE19+Dec!AE19+Jan!AE19+Feb!AE19+Mar!AE19 -> 0 | AF19: =Apr!AF19+May!AF19+Jun!AF19+Jul!AF19+Aug!AF19+Sep!AF19+Oct!AF19+Nov!AF19+Dec!AF19+Jan!AF19+Feb!AF19+Mar!AF19 -> 0 | AG19: =Apr!AG19+May!AG19+Jun!AG19+Jul!AG19+Aug!AG19+Sep!AG19+Oct!AG19+Nov!AG19+Dec!AG19+Jan!AG19+Feb!AG19+Mar!AG19 -> 0 | AI19: =SUM(AE19:AH19) -> 0 | AJ19: =Apr!AJ19+May!AJ19+Jun!AJ19+Jul!AJ19+Aug!AJ19+Sep!AJ19+Oct!AJ19+Nov!AJ19+Dec!AJ19+Jan!AJ19+Feb!AJ19+Mar!AJ19 -> 0 | AK19: =AD19+AI19+AJ19 -> 0 | AL19: =IF(H19="Exempt",0,ROUND((AD19*H19/100)-SUM(AE19:AG19),2)) -> 0 | AO19: Others | AP19: Others | AQ19: RCM Invoice | AR19: 5
A20: =+A19+1 -> 5 | J20: =Apr!J20+May!J20+Jun!J20+Jul!J20+Aug!J20+Sep!J20+Oct!J20+Nov!J20+Dec!J20+Jan!J20+Feb!J20+Mar!J20 -> 0 | K20: =Apr!K20+May!K20+Jun!K20+Jul!K20+Aug!K20+Sep!K20+Oct!K20+Nov!K20+Dec!K20+Jan!K20+Feb!K20+Mar!K20 -> 0 | L20: =Apr!L20+May!L20+Jun!L20+Jul!L20+Aug!L20+Sep!L20+Oct!L20+Nov!L20+Dec!L20+Jan!L20+Feb!L20+Mar!L20 -> 0 | M20: =Apr!M20+May!M20+Jun!M20+Jul!M20+Aug!M20+Sep!M20+Oct!M20+Nov!M20+Dec!M20+Jan!M20+Feb!M20+Mar!M20 -> 0 | N20: =Apr!N20+May!N20+Jun!N20+Jul!N20+Aug!N20+Sep!N20+Oct!N20+Nov!N20+Dec!N20+Jan!N20+Feb!N20+Mar!N20 -> 0 | O20: =SUM(K20:N20) -> 0 | P20: =Apr!P20+May!P20+Jun!P20+Jul!P20+Aug!P20+Sep!P20+Oct!P20+Nov!P20+Dec!P20+Jan!P20+Feb!P20+Mar!P20 -> 0 | Q20: =J20+O20+P20 -> 0 | R20: =IF(H20="Exempt",0,ROUND((J20*H20/100)-SUM(K20:M20),2)) -> 0 | T20: =Apr!T20+May!T20+Jun!T20+Jul!T20+Aug!T20+Sep!T20+Oct!T20+Nov!T20+Dec!T20+Jan!T20+Feb!T20+Mar!T20 -> 0 | U20: =Apr!U20+May!U20+Jun!U20+Jul!U20+Aug!U20+Sep!U20+Oct!U20+Nov!U20+Dec!U20+Jan!U20+Feb!U20+Mar!U20 -> 0 | V20: =Apr!V20+May!V20+Jun!V20+Jul!V20+Aug!V20+Sep!V20+Oct!V20+Nov!V20+Dec!V20+Jan!V20+Feb!V20+Mar!V20 -> 0 | W20: =Apr!W20+May!W20+Jun!W20+Jul!W20+Aug!W20+Sep!W20+Oct!W20+Nov!W20+Dec!W20+Jan!W20+Feb!W20+Mar!W20 -> 0 | X20: =Apr!X20+May!X20+Jun!X20+Jul!X20+Aug!X20+Sep!X20+Oct!X20+Nov!X20+Dec!X20+Jan!X20+Feb!X20+Mar!X20 -> 0 | Y20: =SUM(U20:X20) -> 0 | Z20: =Apr!Z20+May!Z20+Jun!Z20+Jul!Z20+Aug!Z20+Sep!Z20+Oct!Z20+Nov!Z20+Dec!Z20+Jan!Z20+Feb!Z20+Mar!Z20 -> 0 | AA20: =T20+Y20+Z20 -> 0 | AB20: =IF(H20="Exempt",0,ROUND((T20*H20/100)-SUM(U20:W20),2)) -> 0 | AD20: =Apr!AD20+May!AD20+Jun!AD20+Jul!AD20+Aug!AD20+Sep!AD20+Oct!AD20+Nov!AD20+Dec!AD20+Jan!AD20+Feb!AD20+Mar!AD20 -> 0 | AE20: =Apr!AE20+May!AE20+Jun!AE20+Jul!AE20+Aug!AE20+Sep!AE20+Oct!AE20+Nov!AE20+Dec!AE20+Jan!AE20+Feb!AE20+Mar!AE20 -> 0 | AF20: =Apr!AF20+May!AF20+Jun!AF20+Jul!AF20+Aug!AF20+Sep!AF20+Oct!AF20+Nov!AF20+Dec!AF20+Jan!AF20+Feb!AF20+Mar!AF20 -> 0 | AG20: =Apr!AG20+May!AG20+Jun!AG20+Jul!AG20+Aug!AG20+Sep!AG20+Oct!AG20+Nov!AG20+Dec!AG20+Jan!AG20+Feb!AG20+Mar!AG20 -> 0 | AI20: =SUM(AE20:AH20) -> 0 | AJ20: =Apr!AJ20+May!AJ20+Jun!AJ20+Jul!AJ20+Aug!AJ20+Sep!AJ20+Oct!AJ20+Nov!AJ20+Dec!AJ20+Jan!AJ20+Feb!AJ20+Mar!AJ20 -> 0 | AK20: =AD20+AI20+AJ20 -> 0 | AL20: =IF(H20="Exempt",0,ROUND((AD20*H20/100)-SUM(AE20:AG20),2)) -> 0 | AQ20: Challan | AR20: 3
